Workbook

Sheet Recap Finale
A3: Row Labels | B3: Count of Commune
A4: BT Ambovombe | B4: 21
A5: BT Ampanihy | B5: 6
A6: BT Manakara | B6: 18
A7: BT Toliara | B7: 9
A8: (blank)
A9: Grand Total | B9: 54
A12: Count of Commune | B12: Column Labels
A13: Row Labels | B13: Convergence | C13: Urgence | D13: Grand Total
A14: BT Ambovombe | B14: 13 | C14: 8 | D14: 21
A15: BT Ampanihy | B15: 4 | C15: 2 | D15: 6
A16: BT Manakara | B16: 11 | C16: 7 | D16: 18
A17: BT Toliara | B17: 4 | C17: 4 | D17: 8
A18: Grand Total | B18: 32 | C18: 21 | D18: 53
B21: Column Labels
B22: Sum of GAP par type d'activité | D22: Sum of Gap avec marge d'erreur et plainte | F22: Sum of Mng à assister 2025 | H22: Total Sum of GAP par type d'activité | I22: Total Sum of Gap avec marge d'erreur et plainte | J22: Total Sum of Mng à assister 2025
A23: Row Labels | B23: Convergence | C23: Urgence | D23: Convergence | E23: Urgence | F23: Convergence | G23: Urgence
A24: BT Ambovombe | B24: 21069.06 | C24: 5090.1136 | D24: 27863.559 | E24: 8372.9093 | F24: 45296.66 | G24: 21885.305 | H24: 26159.173 | I24: 36236.468 | J24: 67181.964
A25: BT Ampanihy | B25: 20183.749 | C25: 9427.357 | D25: 24742.962 | E25: 10901.461 | F25: 30394.749 | G25: 9827.357 | H25: 29611.106 | I25: 35644.422 | J25: 40222.106
A26: BT Manakara | B26: 3033.2967 | C26: 3929.4611 | D26: 5108.0584 | E26: 5401.8394 | F26: 13831.745 | G26: 9815.8556 | H26: 6962.7577 | I26: 10509.898 | J26: 23647.6
A27: BT Toliara | B27: 3507.1442 | C27: 5448.2868 | D27: 5022.6458 | E27: 6571.8499 | F27: 10103.344 | G27: 7490.4202 | H27: 8955.431 | I27: 11594.496 | J27: 17593.764
A28: Grand Total | B28: 47793.25 | C28: 23895.218 | D28: 62737.225 | E28: 31248.059 | F28: 99626.498 | G28: 49018.937 | H28: 71688.468 | I28: 93985.284 | J28: 148645.44
A32: Count of Commune | B32: Column Labels
A33: Row Labels | B33: Convergence | C33: Résilience | D33: Grand Total
A34: BT Ambovombe | B34: 2 | C34: 17 | D34: 19
A35: BT Ampanihy | B35: 4 | C35: 1 | D35: 5
A36: BT Manakara | B36: 9 | C36: 36 | D36: 45
A37: BT Toliara | B37: 4 | C37: 11 | D37: 15
A38: Grand Total | B38: 19 | C38: 65 | D38: 84
A42: Row Labels | B42: Count of Commune | C42: Sum of Gap avec marge d'erreur et plainte | D42: Sum of Nb agent pour 10 j d'enreg
A43: BT Ambovombe | B43: 21 | C43: 36236.468 | D43: 131
A44: Amboasary-Atsimo | B44: 4 | C44: 4687.5634 | D44: 17
A45: Ebelo | B45: 1 | C45: 381 | D45: 2
A46: Ifotaka | B46: 1 | C46: 3487.6534 | D46: 12
A47: Mahaly | B47: 1 | C47: 565.05 | D47: 2
A48: Ranobe | B48: 1 | C48: 253.86 | D48: 1
A49: Ambovombe-Androy | B49: 4 | C49: 6214.6814 | D49: 23
A50: Ambanisarika | B50: 1 | C50: 1936.8038 | D50: 7
A51: Anjeky Ankilikira | B51: 1 | C51: 509.55 | D51: 2
A52: Maroalomainty | B52: 1 | C52: 377.55 | D52: 2
...

Sheet Recap presentation 
B9: Nombre de commune
B10: BT | C10: Convergence | D10: Urgence | E10: Résilience | F10: Commune
B11: BT Ambovombe | C11: 13 | D11: 8 | E11: 17 | F11: =SUM(C11:E11) -> 38
B12: BT Ampanihy | C12: 4 | D12: 2 | E12: 1 | F12: =SUM(C12:E12) -> 7
B13: BT Manakara | C13: 11 | D13: 7 | E13: 36 | F13: =SUM(C13:E13) -> 54
B14: BT Toliara | C14: 4 | D14: 4 | E14: 11 | F14: =SUM(C14:E14) -> 19
B15: Grand Total | C15: 32 | D15: 21 | E15: 65 | F15: =SUM(F11:F14) -> 118
A18: BT | B18: GAP par type d'activité | D18: Mng à assister 2025 | F18: Total GAP par type d'activité | G18: Total Mng à assister 2025
B19: Convergence | C19: Urgence | D19: Convergence | E19: Urgence
A20: BT Ambovombe | B20: 21069.06 | C20: 5090.1136 | D20: 45296.66 | E20: 21885.305 | F20: 26159.173 | G20: 67181.964
A21: BT Ampanihy | B21: 20183.749 | C21: 9427.357 | D21: 30394.749 | E21: 9827.357 | F21: 29611.106 | G21: 40222.106
A22: BT Manakara | B22: 3033.2967 | C22: 3929.4611 | D22: 13831.745 | E22: 9815.8556 | F22: 6962.7577 | G22: 23647.6
A23: BT Toliara | B23: 3507.1442 | C23: 5448.2868 | D23: 10103.344 | E23: 7490.4202 | F23: 8955.431 | G23: 17593.764
A24: Grand Total | B24: 47793.25 | C24: 23895.218 | D24: 99626.498 | E24: 49018.937 | F24: 71688.468 | G24: 148645.44

Sheet Liste_Final_draft_Urg
A1: Région | B1: ADM3_PCODE | C1: BT | D1: District | E1: Commune | F1: Prio_vf_ICA | G1: rang_commu | H1: F2_24_Acti | I1: Interpreta | J1: Recommanda | K1: Commenta_1 | L1: Interpretation | M1: Recomman_1 | N1: Type Activité | O1: FSRP | P1: Concate verif | Q1: Pop 2025 | R1: Mng_2025 | S1: Liste mng disponible | T1: Pourc_dispo | U1: Repartition liste | V1: Pourc_quota | W1: GAP par type d'activité | X1: Approche | Y1: Mng à assister 2025 | Z1: Under2_6% | AA1: FEFA_5% | AB1: FEFA et U2 | AC1: Marge de 12% | AD1: Plainte 3% | AE1: Mng pour traitement (avec 12% de marge d'erreur et 3% de plainte) | AF1: Nut à cibler (avec 11% de marge d'erreur) | AG1: Gap avec marge d'erreur et plainte | AH1: Nb de jour pour 1 agent | AI1: Nb agent pour 10 j d'enreg | AJ1: scoremfi | AK1: mfi_classe | AL1: modalite_maj | AM1: riz_1mois | AN1: Leg_1mois | AO1: huile_1mois | AP1: HEB_1mois | AQ1: CSB_1mois | AR1: LNS_1mois | AS1: riz_3mois | AT1: Leg_3mois | AU1: huile_3mois | AV1: HEB_3mois | AW1: CSB_3mois | AX1: LNS_3mois
A2: Androy | B2: MG23210390 | C2: BT Ambovombe | D2: Bekily | E2: Ambahita | F2: 1 | G2: 2 | H2: Urg_sech | I2: Urgence | J2: Ancienne commune | K2: Urgence | L2: Urgence | M2: Ancienne commune | N2: Urgence | P2: Bekily_Ambahita | Q2: 29541.768 | R2: =Q2/5 -> 5908.3537 | S2: 3640.6727 | T2: =S2*100/R2 -> 61.619072 | U2: =R2*Quota!$I$2/100 -> 4460.807 | V2: =U2*100/R2 -> 75.5 | W2: =U2-S2 -> 820.13429 | X2: Rajout d'enregistrement | Y2: =U2 -> 4460.807 | Z2: =Q2*6% -> 1772.5061 | AA2: =Q2*5% -> 1477.0884 | AB2: =Z2+AA2 -> 3249.5945 | AC2: =Y2*12% -> 535.29684 | AD2: =Y2*3% -> 133.82421 | AE2: =Y2+AC2+AD2 -> 5129.9281 | AF2: =(AB2*11%)+AB2 -> 3607.0499 | AG2: =AE2-S2 -> 1489.2553 | AH2: =AG2/Quota!$J$2 -> 49.641845 | AI2: =CEILING(AG2/(Quota!$J$2*Quota!$K$2),1) -> 5 | AJ2: 3.57 | AK2: 2 | AL2: Inkind | AM2: =Y2*(15*0.0004*5) -> 133.82421 | AN2: =Y2*(15*0.00006*5) -> 20.073632 | AO2: =Y2*(0.000035*15*5) -> 11.709618 | AP2: =Y2*(0.0001*3*5) -> 6.6912105 | AQ2: =Y2*(0.0002*30) -> 26.764842 | AR2: =Y2*(0.0001*30) -> 13.382421 | AS2: =AM2*3 -> 401.47263 | AT2: =AN2*3 -> 60.220895 | AU2: =AO2*3 -> 35.128855 | AV2: =AP2*3 -> 20.073632 | AW2: =AQ2*3 -> 80.294526 | AX2: =AR2*3 -> 40.147263
A3: Atsimo Antsinanana | B3: MG51506330a | C3: BT Manakara | D3: Farafangana | E3: Ambalavato Nord | F3: 1 | G3: 2 | I3: Urgence | J3: Ancienne commune | K3: ok | L3: Urgence | M3: Ancienne commune | N3: Convergence | P3: Farafangana_Ambalavato Nord | Q3: 17251.15 | R3: =Q3/5 -> 3450.2301 | T3: =S3*100/R3 -> 0 | U3: =R3*Quota!$H$2/100 -> 2611.8242 | V3: =U3*100/R3 -> 75.7 | W3: =U3-S3 -> 2611.8242 | X3: Nouveau enrégistrement | Y3: =U3 -> 2611.8242 | Z3: =Q3*6% -> 1035.069 | AA3: =Q3*5% -> 862.55752 | AB3: =Z3+AA3 -> 1897.6265 | AC3: =Y3*12% -> 313.4189 | AD3: =Y3*3% -> 78.354725 | AE3: =Y3+AC3+AD3 -> 3003.5978 | AF3: =(AB3*11%)+AB3 -> 2106.3655 | AG3: =AE3-S3 -> 3003.5978 | AH3: =AG3/Quota!$J$2 -> 100.11993 | AI3: =CEILING(AG3/(Quota!$J$2*Quota!$K$2),1) -> 11 | AJ3: 4.55 | AK3: 3 | AL3: CBT | AS3: =AM3*3 -> 0 | AT3: =AN3*3 -> 0 | AU3: =AO3*3 -> 0 | AV3: =AP3*3 -> 0 | AW3: =AQ3*3 -> 0 | AX3: =AR3*3 -> 0
A4: Androy | B4: MG25214212 | C4: BT Ambovombe | D4: Ambovombe-Androy | E4: Ambanisarika | F4: 1 | G4: 2 | H4: AA | I4: Urgence | J4: Ancienne commune | K4: ok | L4: Urgence | M4: Ancienne commune | N4: Convergence | P4: Ambovombe-Androy_Ambanisarika | Q4: 16589.714 | R4: =Q4/5 -> 3317.9428 | S4: 944 | T4: =S4*100/R4 -> 28.451365 | U4: =R4*Quota!$I$2/100 -> 2505.0468 | V4: =U4*100/R4 -> 75.5 | W4: =U4-S4 -> 1561.0468 | X4: Rajout d'enregistrement | Y4: =U4 -> 2505.0468 | Z4: =Q4*6% -> 995.38283 | AA4: =Q4*5% -> 829.48569 | AB4: =Z4+AA4 -> 1824.8685 | AC4: =Y4*12% -> 300.60562 | AD4: =Y4*3% -> 75.151404 | AE4: =Y4+AC4+AD4 -> 2880.8038 | AF4: =(AB4*11%)+AB4 -> 2025.6041 | AG4: =AE4-S4 -> 1936.8038 | AH4: =AG4/Quota!$J$2 -> 64.560127 | AI4: =CEILING(AG4/(Quota!$J$2*Quota!$K$2),1) -> 7 | AJ4: 4.31 | AK4: 3 | AL4: Inkind | AM4: =Y4*(15*0.0004*5) -> 75.151404 | AN4: =Y4*(15*0.00006*5) -> 11.272711 | AO4: =Y4*(0.000035*15*5) -> 6.5757478 | AP4: =Y4*(0.0001*3*5) -> 3.7575702 | AQ4: =Y4*(0.0002*30) -> 15.030281 | AR4: =Y4*(0.0001*30) -> 7.5151404 | AS4: =AM4*3 -> 225.45421 | AT4: =AN4*3 -> 33.818132 | AU4: =AO4*3 -> 19.727244 | AV4: =AP4*3 -> 11.272711 | AW4: =AQ4*3 -> 45.090842 | AX4: =AR4*3 -> 22.545421
A5: Atsimo Antsinanana | B5: MG53519110 | C5: BT Manakara | D5: Vangaindrano | E5: Ambatolava | F5: 2 | G5: 10 | H5: Urg_cycl | I5: Urgence_Resilience | J5: Ancienne commune | L5: Urgence_Resilience | M5: Ancienne commune | N5: Urgence | P5: Vangaindrano_Ambatolava | Q5: 8313.8845 | R5: =Q5/5 -> 1662.7769 | S5: 1333.1355 | T5: =S5*100/R5 -> 80.175246 | U5: 1333.1355 | V5: =U5*100/R5 -> 80.175246 | W5: =U5-S5 -> 0 | X5: MAJ : plainte et validation | Y5: =U5 -> 1333.1355 | Z5: =Q5*6% -> 498.83307 | AA5: =Q5*5% -> 415.69423 | AB5: =Z5+AA5 -> 914.5273 | AC5: =Y5*12% -> 159.97626 | AD5: =Y5*3% -> 39.994064 | AE5: =Y5+AC5+AD5 -> 1533.1058 | AF5: =(AB5*11%)+AB5 -> 1015.1253 | AG5: =AE5-S5 -> 199.97032 | AH5: =AG5/Quota!$J$2 -> 6.6656774 | AI5: =CEILING(AG5/(Quota!$J$2*Quota!$K$2),1) -> 1 | AJ5: 3.73 | AK5: 2 | AL5: Inkind | AM5: =Y5*(15*0.0004*5) -> 39.994064 | AN5: =Y5*(15*0.00006*5) -> 5.9991096 | AO5: =Y5*(0.000035*15*5) -> 3.4994806 | AP5: =Y5*(0.0001*3*5) -> 1.9997032 | AQ5: =Y5*(0.0002*30) -> 7.9988129 | AR5: =Y5*(0.0001*30) -> 3.9994064 | AS5: =AM5*3 -> 119.98219 | AT5: =AN5*3 -> 17.997329 | AU5: =AO5*3 -> 10.498442 | AV5: =AP5*3 -> 5.9991096 | AW5: =AQ5*3 -> 23.996439 | AX5: =AR5*3 -> 11.998219
A6: Androy | B6: MG51520111 | C6: BT Ambovombe | D6: Beloha | E6: Ambatotsivala | F6: 1 | G6: 2 | I6: Urgence | J6: Ancienne commune | K6: ok | L6: Urgence | M6: Ancienne commune | N6: Convergence | P6: Beloha_Ambatotsivala | Q6: 10526.077 | R6: =Q6/5 -> 2105.2153 | T6: =S6*100/R6 -> 0 | U6: =R6*Quota!$H$2/100 -> 1593.648 | V6: =U6*100/R6 -> 75.7 | W6: =U6-S6 -> 1593.648 | X6: Nouveau enrégistrement | Y6: =U6 -> 1593.648 | Z6: =Q6*6% -> 631.5646 | AA6: =Q6*5% -> 526.30384 | AB6: =Z6+AA6 -> 1157.8684 | AC6: =Y6*12% -> 191.23776 | AD6: =Y6*3% -> 47.809441 | AE6: =Y6+AC6+AD6 -> 1832.6952 | AF6: =(AB6*11%)+AB6 -> 1285.234 | AG6: =AE6-S6 -> 1832.6952 | AH6: =AG6/Quota!$J$2 -> 61.089841 | AI6: =CEILING(AG6/(Quota!$J$2*Quota!$K$2),1) -> 7 | AJ6: 5.03 | AK6: 4 | AL6: CBT | AS6: =AM6*3 -> 0 | AT6: =AN6*3 -> 0 | AU6: =AO6*3 -> 0 | AV6: =AP6*3 -> 0 | AW6: =AQ6*3 -> 0 | AX6: =AR6*3 -> 0
A7: Vatovavy | B7: MG52516033 | C7: BT Manakara | D7: Mananjary | E7: Ambohitsara Est | F7: 2 | G7: 16 | H7: Urg_Cycl | I7: Urgence_Resilience | J7: Ancienne commune | L7: Urgence_Resilience | M7: Ancienne commune | N7: Convergence | P7: Mananjary_Ambohitsara Est | Q7: 7650.202 | R7: =Q7/5 -> 1530.0404 | S7: 1145.0396 | T7: =S7*100/R7 -> 74.837213 | U7: 1145.0396 | V7: =U7*100/R7 -> 74.837213 | W7: =U7-S7 -> 0 | X7: MAJ : plainte et validation | Y7: =U7 -> 1145.0396 | Z7: =Q7*6% -> 459.01212 | AA7: =Q7*5% -> 382.5101 | AB7: =Z7+AA7 -> 841.52222 | AC7: =Y7*12% -> 137.40475 | AD7: =Y7*3% -> 34.351188 | AE7: =Y7+AC7+AD7 -> 1316.7955 | AF7: =(AB7*11%)+AB7 -> 934.08967 | AG7: =AE7-S7 -> 171.75594 | AH7: =AG7/Quota!$J$2 -> 5.725198 | AI7: =CEILING(AG7/(Quota!$J$2*Quota!$K$2),1) -> 1 | AJ7: 4.32 | AK7: 3 | AL7: CBT + Mitigations | AS7: =AM7*3 -> 0 | AT7: =AN7*3 -> 0 | AU7: =AO7*3 -> 0 | AV7: =AP7*3 -> 0 | AW7: =AQ7*3 -> 0 | AX7: =AR7*3 -> 0
A8: Atsimo Antsinanana | B8: MG25213050a | C8: BT Manakara | D8: Vangaindrano | E8: Ambongo | F8: 2 | G8: 9 | I8: Urgence_Resilience | J8: Ancienne commune | L8: Urgence_Resilience | M8: Ancienne commune | N8: Urgence | P8: Vangaindrano_Ambongo | Q8: 10315.873 | R8: =Q8/5 -> 2063.1746 | T8: =S8*100/R8 -> 0 | U8: =R8*Quota!$H$2/100 -> 1561.8232 | V8: =U8*100/R8 -> 75.7 | W8: =U8-S8 -> 1561.8232 | X8: Nouveau enrégistrement | Y8: =U8 -> 1561.8232 | Z8: =Q8*6% -> 618.95238 | AA8: =Q8*5% -> 515.79365 | AB8: =Z8+AA8 -> 1134.746 | AC8: =Y8*12% -> 187.41878 | AD8: =Y8*3% -> 46.854695 | AE8: =Y8+AC8+AD8 -> 1796.0966 | AF8: =(AB8*11%)+AB8 -> 1259.5681 | AG8: =AE8-S8 -> 1796.0966 | AH8: =AG8/Quota!$J$2 -> 59.869888 | AI8: =CEILING(AG8/(Quota!$J$2*Quota!$K$2),1) -> 6 | AJ8: 3.54 | AK8: 2 | AL8: Inkind | AM8: =Y8*(15*0.0004*5) -> 46.854695 | AN8: =Y8*(15*0.00006*5) -> 7.0282043 | AO8: =Y8*(0.000035*15*5) -> 4.0997858 | AP8: =Y8*(0.0001*3*5) -> 2.3427348 | AQ8: =Y8*(0.0002*30) -> 9.370939 | AR8: =Y8*(0.0001*30) -> 4.6854695 | AS8: =AM8*3 -> 140.56409 | AT8: =AN8*3 -> 21.084613 | AU8: =AO8*3 -> 12.299357 | AV8: =AP8*3 -> 7.0282043 | AW8: =AQ8*3 -> 28.112817 | AX8: =AR8*3 -> 14.056409
A9: Fitovinany | B9: MG52516032 | C9: BT Manakara | D9: Vohipeno | E9: Amborobe | F9: 2 | G9: 6 | H9: Urg_cycl | I9: Urgence_Resilience | J9: Ancienne commune | L9: Urgence_Resilience | M9: Ancienne commune | N9: Convergence | P9: Vohipeno_Amborobe | Q9: 4967.4145 | R9: =Q9/5 -> 993.48289 | S9: 609.27328 | T9: =S9*100/R9 -> 61.327003 | U9: =R9*Quota!$I$2/100 -> 750.07958 | V9: =U9*100/R9 -> 75.5 | W9: =U9-S9 -> 140.8063 | X9: Rajout d'enregistrement | Y9: =U9 -> 750.07958 | Z9: =Q9*6% -> 298.04487 | AA9: =Q9*5% -> 248.37072 | AB9: =Z9+AA9 -> 546.41559 | AC9: =Y9*12% -> 90.00955 | AD9: =Y9*3% -> 22.502387 | AE9: =Y9+AC9+AD9 -> 862.59152 | AF9: =(AB9*11%)+AB9 -> 606.52131 | AG9: =AE9-S9 -> 253.31824 | AH9: =AG9/Quota!$J$2 -> 8.4439414 | AI9: =CEILING(AG9/(Quota!$J$2*Quota!$K$2),1) -> 1 | AJ9: 4.1 | AK9: 3 | AL9: Inkind | AM9: =Y9*(15*0.0004*5) -> 22.502387 | AN9: =Y9*(15*0.00006*5) -> 3.3753581 | AO9: =Y9*(0.000035*15*5) -> 1.9689589 | AP9: =Y9*(0.0001*3*5) -> 1.1251194 | AQ9: =Y9*(0.0002*30) -> 4.5004775 | AR9: =Y9*(0.0001*30) -> 2.2502387 | AS9: =AM9*3 -> 67.507162 | AT9: =AN9*3 -> 10.126074 | AU9: =AO9*3 -> 5.9068767 | AV9: =AP9*3 -> 3.3753581 | AW9: =AQ9*3 -> 13.501432 | AX9: =AR9*3 -> 6.7507162
A10: Atsimo Andrefana | B10: MG51520191 | C10: BT Ampanihy | D10: Ampanihy Ouest | E10: Ampanihy Ouest | F10: 1 | G10: 15 | I10: Urgence | J10: Ancienne commune | K10: ok | L10: Urgence | M10: Ancienne commune | N10: Urgence | P10: Ampanihy Ouest_Ampanihy Ouest | Q10: 52754.238 | R10: =Q10/5 -> 10550.848 | T10: =S10*100/R10 -> 0 | U10: =R10*Quota!$H$2/100 -> 7986.9917 | V10: =U10*100/R10 -> 75.7 | W10: =U10-S10 -> 7986.9917 | X10: Nouveau enrégistrement | Y10: =U10 -> 7986.9917 | Z10: =Q10*6% -> 3165.2543 | AA10: =Q10*5% -> 2637.7119 | AB10: =Z10+AA10 -> 5802.9662 | AC10: =Y10*12% -> 958.439 | AD10: =Y10*3% -> 239.60975 | AE10: =Y10+AC10+AD10 -> 9185.0405 | AF10: =(AB10*11%)+AB10 -> 6441.2925 | AG10: =AE10-S10 -> 9185.0405 | AH10: =AG10/Quota!$J$2 -> 306.16802 | AI10: =CEILING(AG10/(Quota!$J$2*Quota!$K$2),1) -> 31 | AJ10: 2.09 | AK10: 1 | AL10: CBT + Mitigations | AS10: =AM10*3 -> 0 | AT10: =AN10*3 -> 0 | AU10: =AO10*3 -> 0 | AV10: =AP10*3 -> 0 | AW10: =AQ10*3 -> 0 | AX10: =AR10*3 -> 0
A11: Atsimo Andrefana | B11: MG23207172 | C11: BT Ampanihy | D11: Ampanihy Ouest | E11: Anavoha | F11: 1 | G11: 5 | H11: AA | I11: Urgence | J11: Ancienne commune | K11: ok | L11: Urgence | M11: Ancienne commune | N11: Urgence | P11: Ampanihy Ouest_Anavoha | Q11: 12187.849 | R11: =Q11/5 -> 2437.5699 | S11: 400 | T11: =S11*100/R11 -> 16.409786 | U11: =R11*Quota!$I$2/100 -> 1840.3653 | V11: =U11*100/R11 -> 75.5 | W11: =U11-S11 -> 1440.3653 | X11: Rajout d'enregistrement | Y11: =U11 -> 1840.3653 | Z11: =Q11*6% -> 731.27097 | AA11: =Q11*5% -> 609.39247 | AB11: =Z11+AA11 -> 1340.6634 | AC11: =Y11*12% -> 220.84383 | AD11: =Y11*3% -> 55.210958 | AE11: =Y11+AC11+AD11 -> 2116.4201 | AF11: =(AB11*11%)+AB11 -> 1488.1364 | AG11: =AE11-S11 -> 1716.4201 | AH11: =AG11/Quota!$J$2 -> 57.214002 | AI11: =CEILING(AG11/(Quota!$J$2*Quota!$K$2),1) -> 6 | AJ11: 4.31 | AK11: 3 | AL11: Inkind | AM11: =Y11*(15*0.0004*5) -> 55.210958 | AN11: =Y11*(15*0.00006*5) -> 8.2816437 | AO11: =Y11*(0.000035*15*5) -> 4.8309588 | AP11: =Y11*(0.0001*3*5) -> 2.7605479 | AQ11: =Y11*(0.0002*30) -> 11.042192 | AR11: =Y11*(0.0001*30) -> 5.5210958 | AS11: =AM11*3 -> 165.63287 | AT11: =AN11*3 -> 24.844931 | AU11: =AO11*3 -> 14.492876 | AV11: =AP11*3 -> 8.2816437 | AW11: =AQ11*3 -> 33.126575 | AX11: =AR11*3 -> 16.563287
A12: Atsimo Antsinanana | B12: MG51506113 | C12: BT Manakara | D12: Vondrozo | E12: Andakana | F12: 1 | G12: 5 | I12: Urgence | J12: Ancienne commune | K12: ok | L12: Urgence | M12: Ancienne commune | N12: Urgence | P12: Vondrozo_Andakana | Q12: 9390.4013 | R12: =Q12/5 -> 1878.0803 | T12: =S12*100/R12 -> 0 | U12: =R12*Quota!$H$2/100 -> 1421.7068 | V12: =U12*100/R12 -> 75.7 | W12: =U12-S12 -> 1421.7068 | X12: Nouveau enrégistrement | Y12: =U12 -> 1421.7068 | Z12: =Q12*6% -> 563.42408 | AA12: =Q12*5% -> 469.52007 | AB12: =Z12+AA12 -> 1032.9441 | AC12: =Y12*12% -> 170.60481 | AD12: =Y12*3% -> 42.651203 | AE12: =Y12+AC12+AD12 -> 1634.9628 | AF12: =(AB12*11%)+AB12 -> 1146.568 | AG12: =AE12-S12 -> 1634.9628 | AH12: =AG12/Quota!$J$2 -> 54.498759 | AI12: =CEILING(AG12/(Quota!$J$2*Quota!$K$2),1) -> 6 | AJ12: 4.62 | AK12: 3 | AL12: CBT | AS12: =AM12*3 -> 0 | AT12: =AN12*3 -> 0 | AU12: =AO12*3 -> 0 | AV12: =AP12*3 -> 0 | AW12: =AQ12*3 -> 0 | AX12: =AR12*3 -> 0
A13: Androy | B13: MG23210052 | C13: BT Ambovombe | D13: Antanimora Sud | E13: Andalatanosy | F13: 1 | G13: 4 | H13: Urg_sech | I13: Urgence | J13: Ancienne commune | K13: ok | L13: Urgence | M13: Ancienne commune | N13: Convergence | P13: Antanimora Sud_Andalatanosy | Q13: 49864.56 | R13: =Q13/5 -> 9972.912 | S13: 6765.6 | T13: =S13*100/R13 -> 67.839764 | U13: =R13*Quota!$I$2/100 -> 7529.5486 | V13: =U13*100/R13 -> 75.5 | W13: =U13-S13 -> 763.94856 | X13: Rajout d'enregistrement | Y13: =U13 -> 7529.5486 | Z13: =Q13*6% -> 2991.8736 | AA13: =Q13*5% -> 2493.228 | AB13: =Z13+AA13 -> 5485.1016 | AC13: =Y13*12% -> 903.54583 | AD13: =Y13*3% -> 225.88646 | AE13: =Y13+AC13+AD13 -> 8658.9808 | AF13: =(AB13*11%)+AB13 -> 6088.4628 | AG13: =AE13-S13 -> 1893.3808 | AH13: =AG13/Quota!$J$2 -> 63.112695 | AI13: =CEILING(AG13/(Quota!$J$2*Quota!$K$2),1) -> 7 | AJ13: 3.61 | AK13: 2 | AL13: Inkind | AM13: =Y13*(15*0.0004*5) -> 225.88646 | AN13: =Y13*(15*0.00006*5) -> 33.882969 | AO13: =Y13*(0.000035*15*5) -> 19.765065 | AP13: =Y13*(0.0001*3*5) -> 11.294323 | AQ13: =Y13*(0.0002*30) -> 45.177291 | AR13: =Y13*(0.0001*30) -> 22.588646 | AS13: =AM13*3 -> 677.65937 | AT13: =AN13*3 -> 101.64891 | AU13: =AO13*3 -> 59.295195 | AV13: =AP13*3 -> 33.882969 | AW13: =AQ13*3 -> 135.53187 | AX13: =AR13*3 -> 67.765937
A14: Atsimo Andrefana | B14: MG25214230 | C14: BT Ampanihy | D14: Ampanihy Ouest | E14: Androipano | F14: 1 | G14: 3 | H14: Urg_sech | I14: Urgence | J14: Ancienne commune | K14: ok | L14: Urgence | M14: Ancienne commune | N14: Convergence | P14: Ampanihy Ouest_Androipano | Q14: 20666.186 | R14: =Q14/5 -> 4133.2373 | S14: 2311 | T14: =S14*100/R14 -> 55.91259 | U14: =R14*Quota!$I$2/100 -> 3120.5941 | V14: =U14*100/R14 -> 75.5 | W14: =U14-S14 -> 809.59413 | X14: Rajout d'enregistrement | Y14: =U14 -> 3120.5941 | Z14: =Q14*6% -> 1239.9712 | AA14: =Q14*5% -> 1033.3093 | AB14: =Z14+AA14 -> 2273.2805 | AC14: =Y14*12% -> 374.4713 | AD14: =Y14*3% -> 93.617824 | AE14: =Y14+AC14+AD14 -> 3588.6833 | AF14: =(AB14*11%)+AB14 -> 2523.3413 | AG14: =AE14-S14 -> 1277.6833 | AH14: =AG14/Quota!$J$2 -> 42.589442 | AI14: =CEILING(AG14/(Quota!$J$2*Quota!$K$2),1) -> 5 | AJ14: 3.32 | AK14: 1 | AL14: Inkind | AM14: =Y14*(15*0.0004*5) -> 93.617824 | AN14: =Y14*(15*0.00006*5) -> 14.042674 | AO14: =Y14*(0.000035*15*5) -> 8.1915596 | AP14: =Y14*(0.0001*3*5) -> 4.6808912 | AQ14: =Y14*(0.0002*30) -> 18.723565 | AR14: =Y14*(0.0001*30) -> 9.3617824 | AS14: =AM14*3 -> 280.85347 | AT14: =AN14*3 -> 42.128021 | AU14: =AO14*3 -> 24.574679 | AV14: =AP14*3 -> 14.042674 | AW14: =AQ14*3 -> 56.170694 | AX14: =AR14*3 -> 28.085347
A15: Atsimo Andrefana | B15: MG25214112 | C15: BT Ampanihy | D15: Ampanihy Ouest | E15: Androka | F15: 1 | G15: 16 | H15: Urg_sech | I15: Urgence | J15: Ancienne commune | K15: ok | L15: Urgence | M15: Ancienne commune | N15: Convergence | P15: Ampanihy Ouest_Androka | Q15: 49359.83 | R15: =Q15/5 -> 9871.9659 | S15: 7000 | T15: =S15*100/R15 -> 70.907862 | U15: =R15*Quota!$I$2/100 -> 7453.3343 | V15: =U15*100/R15 -> 75.5 | W15: =U15-S15 -> 453.33426 | X15: Rajout d'enregistrement | Y15: =U15 -> 7453.3343 | Z15: =Q15*6% -> 2961.5898 | AA15: =Q15*5% -> 2467.9915 | AB15: =Z15+AA15 -> 5429.5812 | AC15: =Y15*12% -> 894.40011 | AD15: =Y15*3% -> 223.60003 | AE15: =Y15+AC15+AD15 -> 8571.3344 | AF15: =(AB15*11%)+AB15 -> 6026.8352 | AG15: =AE15-S15 -> 1571.3344 | AH15: =AG15/Quota!$J$2 -> 52.377813 | AI15: =CEILING(AG15/(Quota!$J$2*Quota!$K$2),1) -> 6 | AJ15: 3.98 | AK15: 2 | AL15: Inkind | AM15: =Y15*(15*0.0004*5) -> 223.60003 | AN15: =Y15*(15*0.00006*5) -> 33.540004 | AO15: =Y15*(0.000035*15*5) -> 19.565002 | AP15: =Y15*(0.0001*3*5) -> 11.180001 | AQ15: =Y15*(0.0002*30) -> 44.720006 | AR15: =Y15*(0.0001*30) -> 22.360003 | AS15: =AM15*3 -> 670.80008 | AT15: =AN15*3 -> 100.62001 | AU15: =AO15*3 -> 58.695007 | AV15: =AP15*3 -> 33.540004 | AW15: =AQ15*3 -> 134.16002 | AX15: =AR15*3 -> 67.080008
A16: Androy | B16: MG25217071 | C16: BT Ambovombe | D16: Ambovombe-Androy | E16: Anjeky Ankilikira | F16: 1 | G16: 1 | H16: Urg_sech | I16: Urgence | J16: Ancienne commune | K16: ok | L16: Urgence | M16: Ancienne commune | N16: Urgence | P16: Ambovombe-Androy_Anjeky Ankilikira | Q16: 19993.402 | R16: =Q16/5 -> 3998.6805 | S16: 3397 | T16: =S16*100/R16 -> 84.953024 | U16: 3397 | V16: =U16*100/R16 -> 84.953024 | W16: =U16-S16 -> 0 | X16: MAJ : plainte et validation | Y16: =U16 -> 3397 | Z16: =Q16*6% -> 1199.6041 | AA16: =Q16*5% -> 999.67012 | AB16: =Z16+AA16 -> 2199.2743 | AC16: =Y16*12% -> 407.64 | AD16: =Y16*3% -> 101.91 | AE16: =Y16+AC16+AD16 -> 3906.55 | AF16: =(AB16*11%)+AB16 -> 2441.1944 | AG16: =AE16-S16 -> 509.55 | AH16: =AG16/Quota!$J$2 -> 16.985 | AI16: =CEILING(AG16/(Quota!$J$2*Quota!$K$2),1) -> 2 | AJ16: 2.53 | AK16: 1 | AL16: CBT + Mitigations | AS16: =AM16*3 -> 0 | AT16: =AN16*3 -> 0 | AU16: =AO16*3 -> 0 | AV16: =AP16*3 -> 0 | AW16: =AQ16*3 -> 0 | AX16: =AR16*3 -> 0
A17: Atsimo Andrefana | B17: MG25213370 | C17: BT Toliara | D17: Betioky Atsimo | E17: Ankazomanga Ouest | F17: 2 | G17: 20 | H17: Urg_sech | I17: Urgence_Resilience | J17: Ancienne commune | K17: ok | L17: Urgence_Resilience | M17: Ancienne commune | N17: Convergence | P17: Betioky Atsimo_Ankazomanga Ouest | Q17: 7435.6769 | R17: =Q17/5 -> 1487.1354 | S17: 725.33333 | T17: =S17*100/R17 -> 48.77386 | U17: =R17*Quota!$I$2/100 -> 1122.7872 | V17: =U17*100/R17 -> 75.5 | W17: =U17-S17 -> 397.45388 | X17: Rajout d'enregistrement | Y17: =U17 -> 1122.7872 | Z17: =Q17*6% -> 446.14062 | AA17: =Q17*5% -> 371.78385 | AB17: =Z17+AA17 -> 817.92446 | AC17: =Y17*12% -> 134.73447 | AD17: =Y17*3% -> 33.683616 | AE17: =Y17+AC17+AD17 -> 1291.2053 | AF17: =(AB17*11%)+AB17 -> 907.89615 | AG17: =AE17-S17 -> 565.87197 | AH17: =AG17/Quota!$J$2 -> 18.862399 | AI17: =CEILING(AG17/(Quota!$J$2*Quota!$K$2),1) -> 2 | AJ17: 4.15 | AK17: 3 | AL17: CBT + Mitigations | AS17: =AM17*3 -> 0 | AT17: =AN17*3 -> 0 | AU17: =AO17*3 -> 0 | AV17: =AP17*3 -> 0 | AW17: =AQ17*3 -> 0 | AX17: =AR17*3 -> 0
A18: Atsimo Andrefana | B18: MG25213190 | C18: BT Toliara | D18: Betioky Atsimo | E18: Ankazombalala | F18: 2 | G18: 16 | H18: Urg_sech | I18: Urgence_Resilience | J18: Ancienne commune | K18: ok | L18: Urgence_Resilience | M18: Ancienne commune | N18: Convergence | P18: Betioky Atsimo_Ankazombalala | Q18: 25604.091 | R18: =Q18/5 -> 5120.8181 | S18: 2400 | T18: =S18*100/R18 -> 46.867511 | U18: =R18*Quota!$I$2/100 -> 3866.2177 | V18: =U18*100/R18 -> 75.5 | W18: =U18-S18 -> 1466.2177 | X18: Rajout d'enregistrement | Y18: =U18 -> 3866.2177 | Z18: =Q18*6% -> 1536.2454 | AA18: =Q18*5% -> 1280.2045 | AB18: =Z18+AA18 -> 2816.45 | AC18: =Y18*12% -> 463.94612 | AD18: =Y18*3% -> 115.98653 | AE18: =Y18+AC18+AD18 -> 4446.1503 | AF18: =(AB18*11%)+AB18 -> 3126.2595 | AG18: =AE18-S18 -> 2046.1503 | AH18: =AG18/Quota!$J$2 -> 68.205011 | AI18: =CEILING(AG18/(Quota!$J$2*Quota!$K$2),1) -> 7 | AJ18: 4.47 | AK18: 3 | AL18: CBT + Mitigations | AS18: =AM18*3 -> 0 | AT18: =AN18*3 -> 0 | AU18: =AO18*3 -> 0 | AV18: =AP18*3 -> 0 | AW18: =AQ18*3 -> 0 | AX18: =AR18*3 -> 0
A19: Fitovinany | B19: MG25213350 | C19: BT Manakara | D19: Vohipeno | E19: Anoloka | F19: 1 | G19: 4 | H19: Urg_cycl | I19: Urgence | J19: Ancienne commune | K19: ok | L19: Urgence | M19: Ancienne commune | N19: Convergence | P19: Vohipeno_Anoloka | Q19: 3885.6646 | R19: =Q19/5 -> 777.13292 | S19: 582.96027 | T19: =S19*100/R19 -> 75.014229 | U19: 582.96027 | V19: =U19*100/R19 -> 75.014229 | W19: =U19-S19 -> 0 | X19: MAJ : plainte et validation | Y19: =U19 -> 582.96027 | Z19: =Q19*6% -> 233.13988 | AA19: =Q19*5% -> 194.28323 | AB19: =Z19+AA19 -> 427.42311 | AC19: =Y19*12% -> 69.955233 | AD19: =Y19*3% -> 17.488808 | AE19: =Y19+AC19+AD19 -> 670.40431 | AF19: =(AB19*11%)+AB19 -> 474.43965 | AG19: =AE19-S19 -> 87.444041 | AH19: =AG19/Quota!$J$2 -> 2.9148014 | AI19: =CEILING(AG19/(Quota!$J$2*Quota!$K$2),1) -> 1 | AJ19: 3.34 | AK19: 1 | AL19: Inkind | AM19: =Y19*(15*0.0004*5) -> 17.488808 | AN19: =Y19*(15*0.00006*5) -> 2.6233212 | AO19: =Y19*(0.000035*15*5) -> 1.5302707 | AP19: =Y19*(0.0001*3*5) -> 0.87444041 | AQ19: =Y19*(0.0002*30) -> 3.4977616 | AR19: =Y19*(0.0001*30) -> 1.7488808 | AS19: =AM19*3 -> 52.466425 | AT19: =AN19*3 -> 7.8699637 | AU19: =AO19*3 -> 4.5908122 | AV19: =AP19*3 -> 2.6233212 | AW19: =AQ19*3 -> 10.493285 | AX19: =AR19*3 -> 5.2466425
A20: Fitovinany | B20: MG53517350 | C20: BT Manakara | D20: Manakara Atsimo | E20: Anosiala | F20: 2 | G20: 25 | H20: Urg_Cycl | I20: Urgence_Resilience | J20: Ancienne commune | L20: Urgence_Resilience | M20: Ancienne commune | N20: Urgence | P20: Manakara Atsimo_Anosiala | Q20: 11040.564 | R20: =Q20/5 -> 2208.1129 | S20: 1958.9112 | T20: =S20*100/R20 -> 88.714269 | U20: 1958.9112 | V20: =U20*100/R20 -> 88.714269 | W20: =U20-S20 -> 0 | X20: MAJ : plainte et validation | Y20: =U20 -> 1958.9112 | Z20: =Q20*6% -> 662.43386 | AA20: =Q20*5% -> 552.02822 | AB20: =Z20+AA20 -> 1214.4621 | AC20: =Y20*12% -> 235.06934 | AD20: =Y20*3% -> 58.767336 | AE20: =Y20+AC20+AD20 -> 2252.7479 | AF20: =(AB20*11%)+AB20 -> 1348.0529 | AG20: =AE20-S20 -> 293.83668 | AH20: =AG20/Quota!$J$2 -> 9.7945559 | AI20: =CEILING(AG20/(Quota!$J$2*Quota!$K$2),1) -> 1 | AJ20: 4.61 | AK20: 3 | AL20: CBT | AS20: =AM20*3 -> 0 | AT20: =AN20*3 -> 0 | AU20: =AO20*3 -> 0 | AV20: =AP20*3 -> 0 | AW20: =AQ20*3 -> 0 | AX20: =AR20*3 -> 0
A21: Androy | B21: MG23210032 | C21: BT Ambovombe | D21: Antanimora Sud | E21: Antanimora Atsimo | F21: 1 | G21: 5 | H21: Urg_sech | I21: Urgence | J21: Ancienne commune | K21: ok | L21: Urgence | M21: Ancienne commune | N21: Convergence | P21: Antanimora Sud_Antanimora Atsimo | Q21: 39572.454 | R21: =Q21/5 -> 7914.4908 | S21: 5280.6 | T21: =S21*100/R21 -> 66.720653 | U21: =R21*Quota!$I$2/100 -> 5975.4406 | V21: =U21*100/R21 -> 75.5 | W21: =U21-S21 -> 694.84058 | X21: Rajout d'enregistrement | Y21: =U21 -> 5975.4406 | Z21: =Q21*6% -> 2374.3472 | AA21: =Q21*5% -> 1978.6227 | AB21: =Z21+AA21 -> 4352.97 | AC21: =Y21*12% -> 717.05287 | AD21: =Y21*3% -> 179.26322 | AE21: =Y21+AC21+AD21 -> 6871.7567 | AF21: =(AB21*11%)+AB21 -> 4831.7967 | AG21: =AE21-S21 -> 1591.1567 | AH21: =AG21/Quota!$J$2 -> 53.038556 | AI21: =CEILING(AG21/(Quota!$J$2*Quota!$K$2),1) -> 6 | AJ21: 3.55 | AK21: 2 | AL21: Inkind | AM21: =Y21*(15*0.0004*5) -> 179.26322 | AN21: =Y21*(15*0.00006*5) -> 26.889483 | AO21: =Y21*(0.000035*15*5) -> 15.685532 | AP21: =Y21*(0.0001*3*5) -> 8.9631609 | AQ21: =Y21*(0.0002*30) -> 35.852643 | AR21: =Y21*(0.0001*30) -> 17.926322 | AS21: =AM21*3 -> 537.78965 | AT21: =AN21*3 -> 80.668448 | AU21: =AO21*3 -> 47.056595 | AV21: =AP21*3 -> 26.889483 | AW21: =AQ21*3 -> 107.55793 | AX21: =AR21*3 -> 53.778965
A22: Androy | B22: MG23206012 | C22: BT Ambovombe | D22: Bekily | E22: Antsakoamaro | F22: 1 | G22: 3 | H22: Urg_sech | I22: Urgence | J22: Ancienne commune | K22: ok | L22: Urgence | M22: Ancienne commune | N22: Urgence | P22: Bekily_Antsakoamaro | Q22: 10954.806 | R22: =Q22/5 -> 2190.9611 | S22: 1781.1182 | T22: =S22*100/R22 -> 81.29392 | U22: 1781.1182 | V22: =U22*100/R22 -> 81.29392 | W22: =U22-S22 -> 0 | X22: MAJ : plainte et validation | Y22: =U22 -> 1781.1182 | Z22: =Q22*6% -> 657.28833 | AA22: =Q22*5% -> 547.74028 | AB22: =Z22+AA22 -> 1205.0286 | AC22: =Y22*12% -> 213.73418 | AD22: =Y22*3% -> 53.433545 | AE22: =Y22+AC22+AD22 -> 2048.2859 | AF22: =(AB22*11%)+AB22 -> 1337.5818 | AG22: =AE22-S22 -> 267.16773 | AH22: =AG22/Quota!$J$2 -> 8.9055909 | AI22: =CEILING(AG22/(Quota!$J$2*Quota!$K$2),1) -> 1 | AJ22: 3.37 | AK22: 1 | AL22: Inkind | AM22: =Y22*(15*0.0004*5) -> 53.433545 | AN22: =Y22*(15*0.00006*5) -> 8.0150318 | AO22: =Y22*(0.000035*15*5) -> 4.6754352 | AP22: =Y22*(0.0001*3*5) -> 2.6716773 | AQ22: =Y22*(0.0002*30) -> 10.686709 | AR22: =Y22*(0.0001*30) -> 5.3433545 | AS22: =AM22*3 -> 160.30064 | AT22: =AN22*3 -> 24.045095 | AU22: =AO22*3 -> 14.026306 | AV22: =AP22*3 -> 8.0150318 | AW22: =AQ22*3 -> 32.060127 | AX22: =AR22*3 -> 16.030064
A23: Androy | B23: MG23207010 | C23: BT Ambovombe | D23: Beloha | E23: Behabobo | F23: 1 | G23: 1 | I23: Urgence | J23: Ancienne commune | K23: ok | L23: Urgence | M23: Ancienne commune | N23: Convergence | P23: Beloha_Behabobo | Q23: 9007.2265 | R23: =Q23/5 -> 1801.4453 | T23: =S23*100/R23 -> 0 | U23: =R23*Quota!$H$2/100 -> 1363.6941 | V23: =U23*100/R23 -> 75.7 | W23: =U23-S23 -> 1363.6941 | X23: Nouveau enrégistrement | Y23: =U23 -> 1363.6941 | Z23: =Q23*6% -> 540.43359 | AA23: =Q23*5% -> 450.36132 | AB23: =Z23+AA23 -> 990.79491 | AC23: =Y23*12% -> 163.64329 | AD23: =Y23*3% -> 40.910823 | AE23: =Y23+AC23+AD23 -> 1568.2482 | AF23: =(AB23*11%)+AB23 -> 1099.7824 | AG23: =AE23-S23 -> 1568.2482 | AH23: =AG23/Quota!$J$2 -> 52.27494 | AI23: =CEILING(AG23/(Quota!$J$2*Quota!$K$2),1) -> 6 | AJ23: 4.85 | AK23: 3 | AL23: CBT + Mitigations | AS23: =AM23*3 -> 0 | AT23: =AN23*3 -> 0 | AU23: =AO23*3 -> 0 | AV23: =AP23*3 -> 0 | AW23: =AQ23*3 -> 0 | AX23: =AR23*3 -> 0
A24: Anosy | B24: MG25222031a | C24: BT Ambovombe | D24: Amboasary-Atsimo | E24: Ebelo | F24: 2 | G24: 8 | H24: Urg_sech | I24: Urgence_Resilience | J24: Ancienne commune | K24: ok | L24: Urgence_Resilience | M24: Ancienne commune | N24: Convergence | P24: Amboasary-Atsimo_Ebelo | Q24: 13316.715 | R24: =Q24/5 -> 2663.343 | S24: 2540 | T24: =S24*100/R24 -> 95.368864 | U24: 2540 | V24: =U24*100/R24 -> 95.368864 | W24: =U24-S24 -> 0 | X24: MAJ : plainte et validation | Y24: =U24 -> 2540 | Z24: =Q24*6% -> 799.00291 | AA24: =Q24*5% -> 665.83576 | AB24: =Z24+AA24 -> 1464.8387 | AC24: =Y24*12% -> 304.8 | AD24: =Y24*3% -> 76.2 | AE24: =Y24+AC24+AD24 -> 2921 | AF24: =(AB24*11%)+AB24 -> 1625.9709 | AG24: =AE24-S24 -> 381 | AH24: =AG24/Quota!$J$2 -> 12.7 | AI24: =CEILING(AG24/(Quota!$J$2*Quota!$K$2),1) -> 2 | AJ24: 4.2 | AK24: 3 | AL24: Inkind | AM24: =Y24*(15*0.0004*5) -> 76.2 | AN24: =Y24*(15*0.00006*5) -> 11.43 | AO24: =Y24*(0.000035*15*5) -> 6.6675 | AP24: =Y24*(0.0001*3*5) -> 3.81 | AQ24: =Y24*(0.0002*30) -> 15.24 | AR24: =Y24*(0.0001*30) -> 7.62 | AS24: =AM24*3 -> 228.6 | AT24: =AN24*3 -> 34.29 | AU24: =AO24*3 -> 20.0025 | AV24: =AP24*3 -> 11.43 | AW24: =AQ24*3 -> 45.72 | AX24: =AR24*3 -> 22.86
A25: Atsimo Andrefana | B25: MG25214092 | C25: BT Ampanihy | D25: Ampanihy Ouest | E25: Ejeda | F25: 1 | G25: 2 | H25: AA | I25: Urgence | J25: Ancienne commune | K25: ok | L25: Urgence | M25: Ancienne commune | N25: Convergence | P25: Ampanihy Ouest_Ejeda | Q25: 65728.566 | R25: =Q25/5 -> 13145.713 | S25: 400 | T25: =S25*100/R25 -> 3.042817 | U25: =R25*Quota!$I$2/100 -> 9925.0135 | V25: =U25*100/R25 -> 75.5 | W25: =U25-S25 -> 9525.0135 | X25: Rajout d'enregistrement | Y25: =U25 -> 9925.0135 | Z25: =Q25*6% -> 3943.714 | AA25: =Q25*5% -> 3286.4283 | AB25: =Z25+AA25 -> 7230.1423 | AC25: =Y25*12% -> 1191.0016 | AD25: =Y25*3% -> 297.7504 | AE25: =Y25+AC25+AD25 -> 11413.765 | AF25: =(AB25*11%)+AB25 -> 8025.4579 | AG25: =AE25-S25 -> 11013.765 | AH25: =AG25/Quota!$J$2 -> 367.12552 | AI25: =CEILING(AG25/(Quota!$J$2*Quota!$K$2),1) -> 37 | AJ25: 3.32 | AK25: 1 | AL25: Inkind | AM25: =Y25*(15*0.0004*5) -> 297.7504 | AN25: =Y25*(15*0.00006*5) -> 44.662561 | AO25: =Y25*(0.000035*15*5) -> 26.05316 | AP25: =Y25*(0.0001*3*5) -> 14.88752 | AQ25: =Y25*(0.0002*30) -> 59.550081 | AR25: =Y25*(0.0001*30) -> 29.77504 | AS25: =AM25*3 -> 893.25121 | AT25: =AN25*3 -> 133.98768 | AU25: =AO25*3 -> 78.159481 | AV25: =AP25*3 -> 44.662561 | AW25: =AQ25*3 -> 178.65024 | AX25: =AR25*3 -> 89.325121
A26: Atsimo Andrefana | B26: MG25214131 | C26: BT Ampanihy | D26: Ampanihy Ouest | E26: Fotadrevo | F26: 1 | G26: 6 | H26: AA | I26: Urgence | J26: Ancienne commune | K26: ok | L26: Urgence | M26: Ancienne commune | N26: Convergence | P26: Ampanihy Ouest_Fotadrevo | Q26: 65535.149 | R26: =Q26/5 -> 13107.03 | S26: 500 | T26: =S26*100/R26 -> 3.8147468 | U26: =R26*Quota!$I$2/100 -> 9895.8075 | V26: =U26*100/R26 -> 75.5 | W26: =U26-S26 -> 9395.8075 | X26: Rajout d'enregistrement | Y26: =U26 -> 9895.8075 | Z26: =Q26*6% -> 3932.1089 | AA26: =Q26*5% -> 3276.7574 | AB26: =Z26+AA26 -> 7208.8664 | AC26: =Y26*12% -> 1187.4969 | AD26: =Y26*3% -> 296.87422 | AE26: =Y26+AC26+AD26 -> 11380.179 | AF26: =(AB26*11%)+AB26 -> 8001.8417 | AG26: =AE26-S26 -> 10880.179 | AH26: =AG26/Quota!$J$2 -> 362.67262 | AI26: =CEILING(AG26/(Quota!$J$2*Quota!$K$2),1) -> 37 | AJ26: 3.41 | AK26: 1 | AL26: Inkind | AM26: =Y26*(15*0.0004*5) -> 296.87422 | AN26: =Y26*(15*0.00006*5) -> 44.531134 | AO26: =Y26*(0.000035*15*5) -> 25.976495 | AP26: =Y26*(0.0001*3*5) -> 14.843711 | AQ26: =Y26*(0.0002*30) -> 59.374845 | AR26: =Y26*(0.0001*30) -> 29.687422 | AS26: =AM26*3 -> 890.62267 | AT26: =AN26*3 -> 133.5934 | AU26: =AO26*3 -> 77.929484 | AV26: =AP26*3 -> 44.531134 | AW26: =AQ26*3 -> 178.12453 | AX26: =AR26*3 -> 89.062267
A27: Atsimo Antsinanana | B27: MG51506015 | C27: BT Manakara | D27: Vondrozo | E27: Iamonta | F27: 1 | G27: 4 | I27: Urgence | J27: Ancienne commune | K27: ok | L27: Urgence | M27: Ancienne commune | N27: Urgence | P27: Vondrozo_Iamonta | Q27: 6247.8938 | R27: =Q27/5 -> 1249.5788 | T27: =S27*100/R27 -> 0 | U27: =R27*Quota!$H$2/100 -> 945.93112 | V27: =U27*100/R27 -> 75.7 | W27: =U27-S27 -> 945.93112 | X27: Nouveau enrégistrement | Y27: =U27 -> 945.93112 | Z27: =Q27*6% -> 374.87363 | AA27: =Q27*5% -> 312.39469 | AB27: =Z27+AA27 -> 687.26832 | AC27: =Y27*12% -> 113.51173 | AD27: =Y27*3% -> 28.377934 | AE27: =Y27+AC27+AD27 -> 1087.8208 | AF27: =(AB27*11%)+AB27 -> 762.86783 | AG27: =AE27-S27 -> 1087.8208 | AH27: =AG27/Quota!$J$2 -> 36.260693 | AI27: =CEILING(AG27/(Quota!$J$2*Quota!$K$2),1) -> 4 | AJ27: 4.52 | AK27: 3 | AL27: CBT | AS27: =AM27*3 -> 0 | AT27: =AN27*3 -> 0 | AU27: =AO27*3 -> 0 | AV27: =AP27*3 -> 0 | AW27: =AQ27*3 -> 0 | AX27: =AR27*3 -> 0
A28: Anosy | B28: MG51507270 | C28: BT Ambovombe | D28: Amboasary-Atsimo | E28: Ifotaka | F28: 2 | G28: 16 | H28: AA | I28: Urgence_Resilience | J28: Ancienne commune | K28: ok | L28: Urgence_Resilience | M28: Ancienne commune | N28: Convergence | P28: Amboasary-Atsimo_Ifotaka | Q28: 28158.096 | R28: =Q28/5 -> 5631.6192 | S28: 1402 | T28: =S28*100/R28 -> 24.895149 | U28: =R28*Quota!$I$2/100 -> 4251.8725 | V28: =U28*100/R28 -> 75.5 | W28: =U28-S28 -> 2849.8725 | X28: Rajout d'enregistrement | Y28: =U28 -> 4251.8725 | Z28: =Q28*6% -> 1689.4858 | AA28: =Q28*5% -> 1407.9048 | AB28: =Z28+AA28 -> 3097.3906 | AC28: =Y28*12% -> 510.2247 | AD28: =Y28*3% -> 127.55618 | AE28: =Y28+AC28+AD28 -> 4889.6534 | AF28: =(AB28*11%)+AB28 -> 3438.1035 | AG28: =AE28-S28 -> 3487.6534 | AH28: =AG28/Quota!$J$2 -> 116.25511 | AI28: =CEILING(AG28/(Quota!$J$2*Quota!$K$2),1) -> 12 | AJ28: 3.73 | AK28: 2 | AL28: Inkind | AM28: =Y28*(15*0.0004*5) -> 127.55618 | AN28: =Y28*(15*0.00006*5) -> 19.133426 | AO28: =Y28*(0.000035*15*5) -> 11.161165 | AP28: =Y28*(0.0001*3*5) -> 6.3778088 | AQ28: =Y28*(0.0002*30) -> 25.511235 | AR28: =Y28*(0.0001*30) -> 12.755618 | AS28: =AM28*3 -> 382.66853 | AT28: =AN28*3 -> 57.400279 | AU28: =AO28*3 -> 33.483496 | AV28: =AP28*3 -> 19.133426 | AW28: =AQ28*3 -> 76.533705 | AX28: =AR28*3 -> 38.266853
A29: Androy | B29: MG53519250 | C29: BT Ambovombe | D29: Tsihombe | E29: Imongy | F29: 1 | G29: 2 | I29: Urgence | J29: Ancienne commune | K29: ok | L29: Urgence | M29: Ancienne commune | N29: Urgence | P29: Tsihombe_Imongy | Q29: 18126.864 | R29: =Q29/5 -> 3625.3727 | T29: =S29*100/R29 -> 0 | U29: =R29*Quota!$H$2/100 -> 2744.4071 | V29: =U29*100/R29 -> 75.7 | W29: =U29-S29 -> 2744.4071 | X29: Nouveau enrégistrement | Y29: =U29 -> 2744.4071 | Z29: =Q29*6% -> 1087.6118 | AA29: =Q29*5% -> 906.34318 | AB29: =Z29+AA29 -> 1993.955 | AC29: =Y29*12% -> 329.32886 | AD29: =Y29*3% -> 82.332214 | AE29: =Y29+AC29+AD29 -> 3156.0682 | AF29: =(AB29*11%)+AB29 -> 2213.29 | AG29: =AE29-S29 -> 3156.0682 | AH29: =AG29/Quota!$J$2 -> 105.20227 | AI29: =CEILING(AG29/(Quota!$J$2*Quota!$K$2),1) -> 11 | AJ29: 3.56 | AK29: 2 | AL29: Inkind | AM29: =Y29*(15*0.0004*5) -> 82.332214 | AN29: =Y29*(15*0.00006*5) -> 12.349832 | AO29: =Y29*(0.000035*15*5) -> 7.2040688 | AP29: =Y29*(0.0001*3*5) -> 4.1166107 | AQ29: =Y29*(0.0002*30) -> 16.466443 | AR29: =Y29*(0.0001*30) -> 8.2332214 | AS29: =AM29*3 -> 246.99664 | AT29: =AN29*3 -> 37.049496 | AU29: =AO29*3 -> 21.612206 | AV29: =AP29*3 -> 12.349832 | AW29: =AQ29*3 -> 49.399329 | AX29: =AR29*3 -> 24.699664
A30: Fitovinany | B30: MG25213270 | C30: BT Manakara | D30: Vohipeno | E30: Ivato | F30: 1 | G30: 3 | H30: AA | I30: Urgence | J30: Ancienne commune | K30: ok | L30: Urgence | M30: Ancienne commune | N30: Convergence | P30: Vohipeno_Ivato | Q30: 3676.99 | R30: =Q30/5 -> 735.39801 | S30: 1045 | T30: =S30*100/R30 -> 142.09992 | U30: 1045 | V30: =U30*100/R30 -> 142.09992 | W30: =U30-S30 -> 0 | X30: MAJ : plainte et validation | Y30: =U30 -> 1045 | Z30: =Q30*6% -> 220.6194 | AA30: =Q30*5% -> 183.8495 | AB30: =Z30+AA30 -> 404.4689 | AC30: =Y30*12% -> 125.4 | AD30: =Y30*3% -> 31.35 | AE30: =Y30+AC30+AD30 -> 1201.75 | AF30: =(AB30*11%)+AB30 -> 448.96048 | AG30: =AE30-S30 -> 156.75 | AH30: =AG30/Quota!$J$2 -> 5.225 | AI30: =CEILING(AG30/(Quota!$J$2*Quota!$K$2),1) -> 1 | AJ30: 2.56 | AK30: 1 | AL30: CBT + Mitigations | AS30: =AM30*3 -> 0 | AT30: =AN30*3 -> 0 | AU30: =AO30*3 -> 0 | AV30: =AP30*3 -> 0 | AW30: =AQ30*3 -> 0 | AX30: =AR30*3 -> 0
A31: Androy | B31: MG23210351 | C31: BT Ambovombe | D31: Antanimora Sud | E31: Jafaro | F31: 1 | G31: 3 | H31: Urg_sech | I31: Urgence | J31: Ancienne commune | K31: ok | L31: Urgence | M31: Ancienne commune | N31: Convergence | P31: Antanimora Sud_Jafaro | Q31: 40065.231 | R31: =Q31/5 -> 8013.0462 | S31: 5335.4 | T31: =S31*100/R31 -> 66.583917 | U31: =R31*Quota!$I$2/100 -> 6049.8499 | V31: =U31*100/R31 -> 75.5 | W31: =U31-S31 -> 714.44986 | X31: Rajout d'enregistrement | Y31: =U31 -> 6049.8499 | Z31: =Q31*6% -> 2403.9139 | AA31: =Q31*5% -> 2003.2615 | AB31: =Z31+AA31 -> 4407.1754 | AC31: =Y31*12% -> 725.98198 | AD31: =Y31*3% -> 181.4955 | AE31: =Y31+AC31+AD31 -> 6957.3273 | AF31: =(AB31*11%)+AB31 -> 4891.9647 | AG31: =AE31-S31 -> 1621.9273 | AH31: =AG31/Quota!$J$2 -> 54.064245 | AI31: =CEILING(AG31/(Quota!$J$2*Quota!$K$2),1) -> 6 | AJ31: 3.61 | AK31: 2 | AL31: Inkind | AM31: =Y31*(15*0.0004*5) -> 181.4955 | AN31: =Y31*(15*0.00006*5) -> 27.224324 | AO31: =Y31*(0.000035*15*5) -> 15.880856 | AP31: =Y31*(0.0001*3*5) -> 9.0747748 | AQ31: =Y31*(0.0002*30) -> 36.299099 | AR31: =Y31*(0.0001*30) -> 18.14955 | AS31: =AM31*3 -> 544.48649 | AT31: =AN31*3 -> 81.672973 | AU31: =AO31*3 -> 47.642568 | AV31: =AP31*3 -> 27.224324 | AW31: =AQ31*3 -> 108.8973 | AX31: =AR31*3 -> 54.448649
A32: Atsimo Andrefana | B32: MG25213570 | C32: BT Toliara | D32: Betioky Atsimo | E32: Lazarivo | F32: 2 | G32: 10 | H32: Urg_sech | I32: Urgence_Resilience | J32: Ancienne commune | K32: ok | L32: Urgence_Resilience | M32: Ancienne commune | N32: Convergence | P32: Betioky Atsimo_Lazarivo | Q32: 23286.926 | R32: =Q32/5 -> 4657.3852 | S32: 2180 | T32: =S32*100/R32 -> 46.80738 | U32: =R32*Quota!$I$2/100 -> 3516.3259 | V32: =U32*100/R32 -> 75.5 | W32: =U32-S32 -> 1336.3259 | X32: Rajout d'enregistrement | Y32: =U32 -> 3516.3259 | Z32: =Q32*6% -> 1397.2156 | AA32: =Q32*5% -> 1164.3463 | AB32: =Z32+AA32 -> 2561.5619 | AC32: =Y32*12% -> 421.9591 | AD32: =Y32*3% -> 105.48978 | AE32: =Y32+AC32+AD32 -> 4043.7747 | AF32: =(AB32*11%)+AB32 -> 2843.3337 | AG32: =AE32-S32 -> 1863.7747 | AH32: =AG32/Quota!$J$2 -> 62.125824 | AI32: =CEILING(AG32/(Quota!$J$2*Quota!$K$2),1) -> 7 | AJ32: 2.24 | AK32: 1 | AL32: CBT + Mitigations | AS32: =AM32*3 -> 0 | AT32: =AN32*3 -> 0 | AU32: =AO32*3 -> 0 | AV32: =AP32*3 -> 0 | AW32: =AQ32*3 -> 0 | AX32: =AR32*3 -> 0
A33: Androy | B33: MG23209090 | C33: BT Ambovombe | D33: Beloha | E33: Mahaenegne | F33: 1 | G33: 3 | I33: Urgence | J33: Ancienne commune | K33: ok | L33: Urgence | M33: Ancienne commune | N33: Urgence | P33: Beloha_Mahaenegne | Q33: 10076.434 | R33: =Q33/5 -> 2015.2869 | T33: =S33*100/R33 -> 0 | U33: =R33*Quota!$H$2/100 -> 1525.5722 | V33: =U33*100/R33 -> 75.7 | W33: =U33-S33 -> 1525.5722 | X33: Nouveau enrégistrement | Y33: =U33 -> 1525.5722 | Z33: =Q33*6% -> 604.58606 | AA33: =Q33*5% -> 503.82172 | AB33: =Z33+AA33 -> 1108.4078 | AC33: =Y33*12% -> 183.06866 | AD33: =Y33*3% -> 45.767165 | AE33: =Y33+AC33+AD33 -> 1754.408 | AF33: =(AB33*11%)+AB33 -> 1230.3326 | AG33: =AE33-S33 -> 1754.408 | AH33: =AG33/Quota!$J$2 -> 58.480266 | AI33: =CEILING(AG33/(Quota!$J$2*Quota!$K$2),1) -> 6 | AJ33: 3.61 | AK33: 2 | AL33: Inkind | AM33: =Y33*(15*0.0004*5) -> 45.767165 | AN33: =Y33*(15*0.00006*5) -> 6.8650747 | AO33: =Y33*(0.000035*15*5) -> 4.0046269 | AP33: =Y33*(0.0001*3*5) -> 2.2883582 | AQ33: =Y33*(0.0002*30) -> 9.1534329 | AR33: =Y33*(0.0001*30) -> 4.5767165 | AS33: =AM33*3 -> 137.30149 | AT33: =AN33*3 -> 20.595224 | AU33: =AO33*3 -> 12.013881 | AV33: =AP33*3 -> 6.8650747 | AW33: =AQ33*3 -> 27.460299 | AX33: =AR33*3 -> 13.730149
A34: Anosy | B34: MG51506170 | C34: BT Ambovombe | D34: Amboasary-Atsimo | E34: Mahaly | F34: 2 | G34: 9 | H34: Urg_sech | I34: Urgence_Resilience | J34: Ancienne commune | K34: Nous ramenons en priorite 1 car c'est une commune vulnerable aussi bien conjoncturellement que structurelle car deja les speculations sont deja limites en tubercules et mais en bonne periode et elle est toujours exposee a la secheresse d'une facon recu | L34: Urgence_Resilience | M34: Ancienne commune | N34: Urgence | P34: Amboasary-Atsimo_Mahaly | Q34: 20400.49 | R34: =Q34/5 -> 4080.098 | S34: 3767 | T34: =S34*100/R34 -> 92.326214 | U34: 3767 | V34: =U34*100/R34 -> 92.326214 | W34: =U34-S34 -> 0 | X34: MAJ : plainte et validation | Y34: =U34 -> 3767 | Z34: =Q34*6% -> 1224.0294 | AA34: =Q34*5% -> 1020.0245 | AB34: =Z34+AA34 -> 2244.0539 | AC34: =Y34*12% -> 452.04 | AD34: =Y34*3% -> 113.01 | AE34: =Y34+AC34+AD34 -> 4332.05 | AF34: =(AB34*11%)+AB34 -> 2490.8998 | AG34: =AE34-S34 -> 565.05 | AH34: =AG34/Quota!$J$2 -> 18.835 | AI34: =CEILING(AG34/(Quota!$J$2*Quota!$K$2),1) -> 2 | AJ34: 4.52 | AK34: 3 | AL34: CBT | AS34: =AM34*3 -> 0 | AT34: =AN34*3 -> 0 | AU34: =AO34*3 -> 0 | AV34: =AP34*3 -> 0 | AW34: =AQ34*3 -> 0 | AX34: =AR34*3 -> 0
A35: Vatovavy | B35: MG52516151 | C35: BT Manakara | D35: Mananjary | E35: Mahatsara Iefaka | F35: 2 | G35: 17 | H35: Urg_Cycl | I35: Urgence_Resilience | J35: Ancienne commune | L35: Urgence_Resilience | M35: Ancienne commune | N35: Convergence | P35: Mananjary_Mahatsara Iefaka | Q35: 4370.1734 | R35: =Q35/5 -> 874.03468 | S35: 719.96968 | T35: =S35*100/R35 -> 82.373125 | U35: 719.96968 | V35: =U35*100/R35 -> 82.373125 | W35: =U35-S35 -> 0 | X35: MAJ : plainte et validation | Y35: =U35 -> 719.96968 | Z35: =Q35*6% -> 262.2104 | AA35: =Q35*5% -> 218.50867 | AB35: =Z35+AA35 -> 480.71908 | AC35: =Y35*12% -> 86.396362 | AD35: =Y35*3% -> 21.59909 | AE35: =Y35+AC35+AD35 -> 827.96514 | AF35: =(AB35*11%)+AB35 -> 533.59817 | AG35: =AE35-S35 -> 107.99545 | AH35: =AG35/Quota!$J$2 -> 3.5998484 | AI35: =CEILING(AG35/(Quota!$J$2*Quota!$K$2),1) -> 1 | AJ35: 7.07 | AK35: 4 | AL35: CBT | AS35: =AM35*3 -> 0 | AT35: =AN35*3 -> 0 | AU35: =AO35*3 -> 0 | AV35: =AP35*3 -> 0 | AW35: =AQ35*3 -> 0 | AX35: =AR35*3 -> 0
A36: Atsimo Antsinanana | B36: MG51506270 | C36: BT Manakara | D36: Vondrozo | E36: Mahatsinjo | F36: 1 | G36: 1 | H36: Urg_sech | I36: Urgence | J36: Ancienne commune | K36: ok | L36: Urgence | M36: Ancienne commune | N36: Convergence | P36: Vondrozo_Mahatsinjo | Q36: 10081.625 | R36: =Q36/5 -> 2016.325 | S36: 1537.2899 | T36: =S36*100/R36 -> 76.242168 | U36: 1537.2899 | V36: =U36*100/R36 -> 76.242168 | W36: =U36-S36 -> 0 | X36: MAJ : plainte et validation | Y36: =U36 -> 1537.2899 | Z36: =Q36*6% -> 604.8975 | AA36: =Q36*5% -> 504.08125 | AB36: =Z36+AA36 -> 1108.9787 | AC36: =Y36*12% -> 184.47479 | AD36: =Y36*3% -> 46.118697 | AE36: =Y36+AC36+AD36 -> 1767.8834 | AF36: =(AB36*11%)+AB36 -> 1230.9664 | AG36: =AE36-S36 -> 230.59348 | AH36: =AG36/Quota!$J$2 -> 7.6864494 | AI36: =CEILING(AG36/(Quota!$J$2*Quota!$K$2),1) -> 1 | AJ36: 3.12 | AK36: 1 | AL36: CBT + Mitigations | AS36: =AM36*3 -> 0 | AT36: =AN36*3 -> 0 | AU36: =AO36*3 -> 0 | AV36: =AP36*3 -> 0 | AW36: =AQ36*3 -> 0 | AX36: =AR36*3 -> 0
A37: Vatovavy | B37: MG23210171 | C37: BT Manakara | D37: Mananjary | E37: Mahela | F37: 2 | G37: 13 | H37: Urg_Cycl | I37: Urgence_Resilience | J37: Ancienne commune | K37: Zone FSRP où il y a 4 OP | L37: Urgence_Resilience | M37: Ancienne commune | N37: Convergence | O37: Zone FSRP | P37: Mananjary_Mahela | Q37: 10560.853 | R37: =Q37/5 -> 2112.1705 | S37: 1836.3148 | T37: =S37*100/R37 -> 86.939705 | U37: 1836.3148 | V37: =U37*100/R37 -> 86.939705 | W37: =U37-S37 -> 0 | X37: MAJ : plainte et validation | Y37: =U37 -> 1836.3148 | Z37: =Q37*6% -> 633.65116 | AA37: =Q37*5% -> 528.04263 | AB37: =Z37+AA37 -> 1161.6938 | AC37: =Y37*12% -> 220.35778 | AD37: =Y37*3% -> 55.089445 | AE37: =Y37+AC37+AD37 -> 2111.762 | AF37: =(AB37*11%)+AB37 -> 1289.4801 | AG37: =AE37-S37 -> 275.44722 | AH37: =AG37/Quota!$J$2 -> 9.1815741 | AI37: =CEILING(AG37/(Quota!$J$2*Quota!$K$2),1) -> 1 | AJ37: 3.59 | AK37: 2 | AL37: Inkind | AM37: =Y37*(15*0.0004*5) -> 55.089445 | AN37: =Y37*(15*0.00006*5) -> 8.2634167 | AO37: =Y37*(0.000035*15*5) -> 4.8203264 | AP37: =Y37*(0.0001*3*5) -> 2.7544722 | AQ37: =Y37*(0.0002*30) -> 11.017889 | AR37: =Y37*(0.0001*30) -> 5.5089445 | AS37: =AM37*3 -> 165.26833 | AT37: =AN37*3 -> 24.79025 | AU37: =AO37*3 -> 14.460979 | AV37: =AP37*3 -> 8.2634167 | AW37: =AQ37*3 -> 33.053667 | AX37: =AR37*3 -> 16.526833
A38: Fitovinany | B38: MG52516092 | C38: BT Manakara | D38: Manakara Atsimo | E38: Mangatsiotra | F38: 2 | G38: 18 | H38: Urg_Cycl | I38: Urgence_Resilience | J38: Ancienne commune | L38: Urgence_Resilience | M38: Ancienne commune | N38: Convergence | P38: Manakara Atsimo_Mangatsiotra | Q38: 5423.1406 | R38: =Q38/5 -> 1084.6281 | S38: 677.43657 | T38: =S38*100/R38 -> 62.457958 | U38: =R38*Quota!$I$2/100 -> 818.89422 | V38: =U38*100/R38 -> 75.5 | W38: =U38-S38 -> 141.45766 | X38: Rajout d'enregistrement | Y38: =U38 -> 818.89422 | Z38: =Q38*6% -> 325.38843 | AA38: =Q38*5% -> 271.15703 | AB38: =Z38+AA38 -> 596.54546 | AC38: =Y38*12% -> 98.267307 | AD38: =Y38*3% -> 24.566827 | AE38: =Y38+AC38+AD38 -> 941.72836 | AF38: =(AB38*11%)+AB38 -> 662.16546 | AG38: =AE38-S38 -> 264.29179 | AH38: =AG38/Quota!$J$2 -> 8.8097263 | AI38: =CEILING(AG38/(Quota!$J$2*Quota!$K$2),1) -> 1 | AJ38: 4.38 | AK38: 3 | AL38: CBT + Mitigations | AS38: =AM38*3 -> 0 | AT38: =AN38*3 -> 0 | AU38: =AO38*3 -> 0 | AV38: =AP38*3 -> 0 | AW38: =AQ38*3 -> 0 | AX38: =AR38*3 -> 0
A39: Fitovinany | B39: MG23212053 | C39: BT Manakara | D39: Manakara Atsimo | E39: Manjarivo | F39: 2 | G39: 20 | H39: Urg_Cycl | I39: Urgence_Resilience | J39: Ancienne commune | K39: Urg_Cycl | L39: Urgence_Resilience | M39: Ancienne commune | N39: Urgence | P39: Manakara Atsimo_Manjarivo | Q39: 8950.2207 | R39: =Q39/5 -> 1790.0441 | S39: 1504.5377 | T39: =S39*100/R39 -> 84.050311 | U39: 1504.5377 | V39: =U39*100/R39 -> 84.050311 | W39: =U39-S39 -> 0 | X39: MAJ : plainte et validation | Y39: =U39 -> 1504.5377 | Z39: =Q39*6% -> 537.01324 | AA39: =Q39*5% -> 447.51103 | AB39: =Z39+AA39 -> 984.52428 | AC39: =Y39*12% -> 180.54452 | AD39: =Y39*3% -> 45.13613 | AE39: =Y39+AC39+AD39 -> 1730.2183 | AF39: =(AB39*11%)+AB39 -> 1092.8219 | AG39: =AE39-S39 -> 225.68065 | AH39: =AG39/Quota!$J$2 -> 7.5226883 | AI39: =CEILING(AG39/(Quota!$J$2*Quota!$K$2),1) -> 1 | AJ39: 3.99 | AK39: 2 | AL39: Inkind | AM39: =Y39*(15*0.0004*5) -> 45.13613 | AN39: =Y39*(15*0.00006*5) -> 6.7704195 | AO39: =Y39*(0.000035*15*5) -> 3.9494114 | AP39: =Y39*(0.0001*3*5) -> 2.2568065 | AQ39: =Y39*(0.0002*30) -> 9.027226 | AR39: =Y39*(0.0001*30) -> 4.513613 | AS39: =AM39*3 -> 135.40839 | AT39: =AN39*3 -> 20.311259 | AU39: =AO39*3 -> 11.848234 | AV39: =AP39*3 -> 6.7704195 | AW39: =AQ39*3 -> 27.081678 | AX39: =AR39*3 -> 13.540839
A40: Androy | B40: MG23210370 | C40: BT Ambovombe | D40: Ambovombe-Androy | E40: Maroalomainty | F40: 1 | G40: 5 | H40: Res_SO3 | I40: Urgence | J40: Ancienne commune | K40: ok | L40: Urgence | M40: Ancienne commune | N40: Urgence | P40: Ambovombe-Androy_Maroalomainty | Q40: 16818.456 | R40: =Q40/5 -> 3363.6913 | S40: 2517 | T40: =S40*100/R40 -> 74.828508 | U40: 2517 | V40: =U40*100/R40 -> 74.828508 | W40: =U40-S40 -> 0 | X40: MAJ : plainte et validation | Y40: =U40 -> 2517 | Z40: =Q40*6% -> 1009.1074 | AA40: =Q40*5% -> 840.92282 | AB40: =Z40+AA40 -> 1850.0302 | AC40: =Y40*12% -> 302.04 | AD40: =Y40*3% -> 75.51 | AE40: =Y40+AC40+AD40 -> 2894.55 | AF40: =(AB40*11%)+AB40 -> 2053.5335 | AG40: =AE40-S40 -> 377.55 | AH40: =AG40/Quota!$J$2 -> 12.585 | AI40: =CEILING(AG40/(Quota!$J$2*Quota!$K$2),1) -> 2 | AJ40: 4.55 | AK40: 3 | AL40: CBT | AS40: =AM40*3 -> 0 | AT40: =AN40*3 -> 0 | AU40: =AO40*3 -> 0 | AV40: =AP40*3 -> 0 | AW40: =AQ40*3 -> 0 | AX40: =AR40*3 -> 0
...

Sheet Liste_Final_discussion_Res
A1: Région | B1: ADM3_PCODE | C1: BT | D1: District | E1: Commune | F1: Prio_vf_ICA | G1: rang_commu | H1: Nb_populat | I1: F2_24_Acti | J1: Interpreta | K1: Recommanda | L1: Commenta_1 | M1: Interpretation | N1: Recomman_1 | O1: Type Activité | P1: FSRP | Q1: Concate verif | R1: Pop 2025 | S1: Mng_2025 | T1: Liste mng disponible | U1: Quota à assister Résilience | V1: scoremfi | W1: mfi_classe | X1: modalite_maj
A2: Vatovavy | B2: MG23209470 | C2: BT Manakara | D2: Farafangana | E2: Ambalavato Antevato | F2: 2 | G2: 21 | H2: 6930.1572 | J2: Urgence_Resilience | K2: Ancienne commune | L2: zone Norvège et FSRP | M2: Urgence_Resilience | N2: Ancienne commune | O2: Résilience | P2: Zone FSRP | Q2: Farafangana_Ambalavato Antevato | R2: 6930.1572 | S2: =R2/5 -> 1386.0314 | V2: 3.61 | W2: 2 | X2: Inkind
A3: Atsimo Atsinanana | B3: MG25213030 | C3: BT Manakara | D3: Manakara Atsimo | E3: Ambila | F3: 4 | G3: 42 | H3: 19371.957 | J3: Non recommandé | K3: Non recommandé | L3: zone Norvège et FSRP | M3: Non recommandé | N3: Non recommandé | O3: Résilience | P3: Zone FSRP | Q3: Manakara Atsimo_Ambila | R3: 19371.957 | S3: =R3/5 -> 3874.3914 | V3: 3.52 | W3: 2 | X3: Inkind
A4: Atsimo Atsinanana | B4: MG25213330 | C4: BT Manakara | D4: Nosy-Varika | E4: Ambodirian'i Sahafary | F4: 2 | G4: 12 | H4: 24898.236 | I4: Urg_Sech | J4: Urgence_Resilience | K4: Ancienne commune | L4: ok | M4: Urgence_Resilience | N4: Ancienne commune | O4: Convergence | Q4: Nosy-Varika_Ambodirian'i Sahafary | R4: 24898.236 | S4: =R4/5 -> 4979.6471 | T4: 3644.9096 | V4: 3.66 | W4: 2 | X4: Inkind
A5: Vatovavy | B5: MG23209070a | C5: BT Toliara | D5: Toliary-II | E5: Ambohimahavelona | F5: 1 | G5: 4 | H5: 16776.066 | J5: Urgence | K5: Ancienne commune | L5: AA | M5: Urgence | N5: Ancienne commune | O5: Résilience | Q5: Toliary-II_Ambohimahavelona | R5: 16776.066 | S5: =R5/5 -> 3355.2131 | V5: 4.51 | W5: 3 | X5: CBT + Mitigations
A6: Androy | B6: MG52516033 | C6: BT Manakara | D6: Mananjary | E6: Ambohitsara Est | F6: 2 | G6: 16 | H6: 7650.202 | I6: Urg_Cycl | J6: Urgence_Resilience | K6: Ancienne commune | M6: Urgence_Resilience | N6: Ancienne commune | O6: Convergence | Q6: Mananjary_Ambohitsara Est | R6: 7650.202 | S6: =R6/5 -> 1530.0404 | T6: 1145.0396 | V6: 4.32 | W6: 3 | X6: CBT + Mitigations
A7: Fitovinany | B7: MG23210311 | C7: BT Toliara | D7: Toliary-II | E7: Ambolofoty | F7: 2 | G7: 9 | H7: 9166.185 | J7: Urgence_Resilience | K7: Ancienne commune | L7: FFA | M7: Urgence_Resilience | N7: Ancienne commune | O7: Résilience | Q7: Toliary-II_Ambolofoty | R7: 9166.185 | S7: =R7/5 -> 1833.237 | V7: 4.88 | W7: 3 | X7: CBT
A8: Atsimo Atsinanana | B8: MG25214270 | C8: BT Ambovombe | D8: Ambovombe-Androy | E8: Ambovombe | F8: 2 | G8: 7 | H8: 0 | J8: Urgence_Resilience | K8: Ancienne commune | L8: ok | M8: Urgence_Resilience | N8: Ancienne commune | O8: Résilience | Q8: Ambovombe-Androy_Ambovombe | R8: 87710.335 | S8: =R8/5 -> 17542.067 | V8: 4.46 | W8: 3 | X8: CBT + Mitigations
A9: Fitovinany | B9: MG23210151 | C9: BT Manakara | D9: Manakara Atsimo | E9: Ampasimanjeva | F9: 4 | G9: 44 | H9: 13243.64 | I9: Urg_Cycl | J9: Non recommandé | K9: Non recommandé | L9: Zone FSRP où il y a une OP | M9: Non recommandé | N9: Non recommandé | O9: Résilience | P9: Zone FSRP | Q9: Manakara Atsimo_Ampasimanjeva | R9: 13243.64 | S9: =R9/5 -> 2648.728 | T9: 2234.1104 | V9: 3.55 | W9: 2 | X9: Inkind
A10: Fitovinany | B10: MG23210152 | C10: BT Manakara | D10: Farafangana | E10: Amporoforo | F10: 2 | G10: 22 | H10: 15238.921 | J10: Urgence_Resilience | K10: Ancienne commune | L10: zone Norvège | M10: Urgence_Resilience | N10: Ancienne commune | O10: Résilience | Q10: Farafangana_Amporoforo | R10: 15238.921 | S10: =R10/5 -> 3047.7843 | V10: 3.61 | W10: 2 | X10: Inkind
A11: Atsimo Atsinanana | B11: MG25217012 | C11: BT Ambovombe | D11: Ambovombe-Androy | E11: Analamary | F11: 2 | G11: 1 | H11: 0 | J11: Urgence_Resilience | K11: Ancienne commune | L11: ok | M11: Urgence_Resilience | N11: Ancienne commune | O11: Résilience | Q11: Ambovombe-Androy_Analamary | R11: 7092.3249 | S11: =R11/5 -> 1418.465 | V11: 2.86 | W11: 1 | X11: Inkind
A12: Atsimo Atsinanana | B12: MG25213410 | C12: BT Manakara | D12: Mananjary | E12: Andranambolava | F12: 1 | G12: 8 | H12: 6170.2915 | J12: Urgence | K12: Ancienne commune | L12: ok | M12: Urgence | N12: Ancienne commune | O12: Résilience | Q12: Mananjary_Andranambolava | R12: 6170.2915 | S12: =R12/5 -> 1234.0583 | V12: 1.82 | W12: 1 | X12: Inkind
A13: Atsimo Atsinanana | B13: MG25214230 | C13: BT Ampanihy | D13: Ampanihy Ouest | E13: Androipano | F13: 1 | G13: 3 | H13: 0 | I13: Urg_sech | J13: Urgence | K13: Ancienne commune | L13: ok | M13: Urgence | N13: Ancienne commune | O13: Convergence | Q13: Ampanihy Ouest_Androipano | R13: 20666.186 | S13: =R13/5 -> 4133.2373 | T13: 2311 | V13: 3.32 | W13: 1 | X13: Inkind
A14: Atsimo Atsinanana | B14: MG25214112 | C14: BT Ampanihy | D14: Ampanihy Ouest | E14: Androka | F14: 1 | G14: 16 | H14: 49359.83 | I14: Urg_sech | J14: Urgence | K14: Ancienne commune | L14: ok | M14: Urgence | N14: Ancienne commune | O14: Convergence | Q14: Ampanihy Ouest_Androka | R14: 49359.83 | S14: =R14/5 -> 9871.9659 | T14: 7000 | V14: 3.98 | W14: 2 | X14: Inkind
A15: Vatovavy | B15: MG23209252 | C15: BT Ambovombe | D15: Bekily | E15: Anja Nord | F15: 3 | G15: 17 | H15: 4440.2189 | I15: Urg_sech | J15: Resilience | K15: Ancienne commune | L15: ok | M15: Resilience | N15: Ancienne commune | O15: Résilience | Q15: Bekily_Anja Nord | R15: 4440.2189 | S15: =R15/5 -> 888.04378 | T15: 754 | V15: 3.68 | W15: 2 | X15: Inkind
A16: Atsimo Atsinanana | B16: MG25213250 | C16: BT Ambovombe | D16: Tsihombe | E16: Anjampaly | F16: 1 | G16: 3 | H16: 17600.102 | I16: AA | J16: Urgence | K16: Ancienne commune | L16: ok | M16: Urgence | N16: Ancienne commune | O16: Résilience | Q16: Tsihombe_Anjampaly | R16: 17600.102 | S16: =R16/5 -> 3520.0204 | T16: 400 | V16: 4.55 | W16: 3 | X16: CBT
A17: Vatovavy | B17: MG23206071 | C17: BT Ambovombe | D17: Bekily | E17: Ankaranabo Nord | F17: 2 | G17: 8 | H17: 6334.2069 | J17: Urgence_Resilience | K17: Ancienne commune | L17: ok | M17: Urgence_Resilience | N17: Ancienne commune | O17: Résilience | Q17: Bekily_Ankaranabo Nord | R17: 6334.2069 | S17: =R17/5 -> 1266.8414 | V17: 3.45 | W17: 1 | X17: Inkind
A18: Androy | B18: MG52516011 | C18: BT Manakara | D18: Vohipeno | E18: Ankarimbary | F18: 2 | G18: 11 | H18: 6891.0583 | I18: AA | J18: Urgence_Resilience | K18: Ancienne commune | M18: Urgence_Résilience | N18: Ancienne commune | O18: Résilience | Q18: Vohipeno_Ankarimbary | R18: 6891.0583 | S18: =R18/5 -> 1378.2117 | T18: 440 | V18: 6.46 | W18: 4 | X18: CBT
A19: Atsimo Atsinanana | B19: MG25213370 | C19: BT Toliara | D19: Betioky Atsimo | E19: Ankazomanga Ouest | F19: 2 | G19: 20 | H19: 7435.6769 | I19: Urg_sech | J19: Urgence_Resilience | K19: Ancienne commune | L19: ok | M19: Urgence_Resilience | N19: Ancienne commune | O19: Convergence | Q19: Betioky Atsimo_Ankazomanga Ouest | R19: 7435.6769 | S19: =R19/5 -> 1487.1354 | T19: 725.33333 | V19: 4.15 | W19: 3 | X19: CBT + Mitigations
A20: Atsimo Atsinanana | B20: MG25213190 | C20: BT Toliara | D20: Betioky Atsimo | E20: Ankazombalala | F20: 2 | G20: 16 | H20: 25604.091 | I20: Urg_sech | J20: Urgence_Resilience | K20: Ancienne commune | L20: ok | M20: Urgence_Resilience | N20: Ancienne commune | O20: Convergence | Q20: Betioky Atsimo_Ankazombalala | R20: 25604.091 | S20: =R20/5 -> 5120.8181 | T20: 2400 | V20: 4.47 | W20: 3 | X20: CBT + Mitigations
A21: Atsimo Atsinanana | B21: MG25213350 | C21: BT Manakara | D21: Vohipeno | E21: Anoloka | F21: 1 | G21: 4 | H21: 3885.6646 | I21: Urg_cycl | J21: Urgence | K21: Ancienne commune | L21: ok | M21: Urgence | N21: Ancienne commune | O21: Convergence | Q21: Vohipeno_Anoloka | R21: 3885.6646 | S21: =R21/5 -> 777.13292 | T21: 582.96027 | V21: 3.34 | W21: 1 | X21: Inkind
A22: Vatovavy | B22: MG23209170 | C22: BT Toliara | D22: Toliary-II | E22: Antanimena Onilahy | F22: 1 | G22: 1 | H22: 4608.7107 | J22: Urgence | K22: Ancienne commune | L22: FFA | M22: Urgence | N22: Ancienne commune | O22: Résilience | Q22: Toliary-II_Antanimena Onilahy | R22: 4608.7107 | S22: =R22/5 -> 921.74214 | V22: 3.61 | W22: 2 | X22: Inkind
A23: Anosy | B23: MG53517130 | C23: BT Ambovombe | D23: Tsihombe | E23: Antaritarika | F23: 2 | G23: 4 | H23: 20103.199 | I23: AA | J23: Urgence_Resilience | K23: Ancienne commune | L23: ok | M23: Urgence_Resilience | N23: Ancienne commune | O23: Résilience | Q23: Tsihombe_Antaritarika | R23: 20103.199 | S23: =R23/5 -> 4020.6398 | T23: 400 | V23: 2.96 | W23: 1 | X23: CBT + Mitigations
A24: Atsimo Atsinanana | B24: MG25214070 | C24: BT Toliara | D24: Betioky Atsimo | E24: Antohabato | F24: 1 | G24: 3 | H24: 17372.969 | I24: AA | J24: Urgence | K24: Ancienne commune | L24: ok | M24: Urgence | N24: Ancienne commune | O24: Résilience | Q24: Betioky Atsimo_Antohabato | R24: 17372.969 | S24: =R24/5 -> 3474.5938 | T24: 955 | V24: 2.42 | W24: 1 | X24: CBT + Mitigations
A25: Atsimo Atsinanana | B25: MG25213472 | C25: BT Manakara | D25: Farafangana | E25: Antseranambe | F25: 2 | G25: 12 | H25: 6622.9466 | J25: Urgence_Resilience | K25: Ancienne commune | L25: zone où il y a des OP pour FSRP | M25: Urgence_Resilience | N25: Ancienne commune | O25: Résilience | P25: Zone FSRP | Q25: Farafangana_Antseranambe | R25: 6622.9466 | S25: =R25/5 -> 1324.5893 | V25: 4.25 | W25: 3 | X25: Inkind
A26: Vatovavy | B26: MG23209031 | C26: BT Toliara | D26: Betioky Atsimo | E26: Beantake | F26: 2 | G26: 22 | H26: 13863.278 | J26: Urgence_Resilience | K26: Ancienne commune | L26: ok | M26: Urgence_Resilience | N26: Ancienne commune | O26: Résilience | Q26: Betioky Atsimo_Beantake | R26: 13863.278 | S26: =R26/5 -> 2772.6557 | V26: 3.74 | W26: 2 | X26: Inkind
A27: Atsimo Andrefana | B27: MG51507170 | C27: BT Ambovombe | D27: Amboasary-Atsimo | E27: Behara | F27: 3 | G27: 13 | H27: 0 | I27: AA | J27: Resilience | K27: Ancienne commune | L27: ok | M27: Resilience | N27: Ancienne commune | O27: Résilience | Q27: Amboasary-Atsimo_Behara | R27: 32896.889 | S27: =R27/5 -> 6579.3777 | T27: 889 | V27: 3.78 | W27: 2 | X27: CBT + Mitigations
