Workbook
Name tag: Parameter!$A$25:$A$32

Sheet Sheet5 (2)
A3: POIName | B3: POI_code | C3: Activity_tag
A4: A.BEDARO | B4: MG52516190009001 | C4: Treatment of moderate acute malnutrition
A5: ABC DOMINO AMBOLA | B5: 602091001 | C5: School feeding (on-site)
A6: ABC DOMINO ANDRANOTOHOKY | B6: 602171003 | C6: School feeding (on-site)
A7: ABC DOMINO Ankilibory | B7: 605131003 | C7: School feeding (on-site)
A8: ABC DOMINO ANKILIMIVONY | B8: 602091003 | C8: School feeding (on-site)
A9: ABC DOMINO BEHELOKA | B9: 602091009 | C9: School feeding (on-site)
A10: ABC DOMINO Belitsaka | B10: 605131004 | C10: School feeding (on-site)
A11: Adabolava | B11: MG53519190007001 | C11: Treatment of moderate acute malnutrition
A12: AFONDRALAMBO EVAZY | B12: 621050001 | C12: School feeding (on-site)
A13: AFONDRAVOATSY NORD | B13: 609020007 | C13: School feeding (on-site)
A14: AFONDRIAMBITA | B14: 607080013 | C14: School feeding (on-site)
A15: AGNAFONDRAVOAY | B15: MG53517150085001 | C15: Treatment of moderate acute malnutrition
A16: Agnalalava | B16: MG52513030010001 | C16: Treatment of moderate acute malnutrition
A17: AGNALAMENA | B17: 612190022 | C17: School feeding (on-site)
A18: AGNALAMIHOATSE | B18: 609040047 | C18: School feeding (on-site)
A19: Agnalamisaka | B19: MG51507050020001 | C19: Treatment of moderate acute malnutrition
A20: Agnanademby | B20: MG52513030020001 | C20: Treatment of moderate acute malnutrition
A21: AGNANAKIRIHITSE | B21: 609020035 | C21: School feeding (on-site)
A22: AGNANATSAKOA SOATAMEA | B22: 604190013 | C22: School feeding (on-site)
A23: Agnanilahy | B23: MG52516170043 | C23: Prevention of acute malnutrition
A24: Agnaramaike | B24: MG51507050015002 | C24: Treatment of moderate acute malnutrition
A25: AGNARAMAIKY | B25: 605010014 | C25: School feeding (on-site)
A26: Agnaramalinike | B26: MG51507050015001 | C26: Treatment of moderate acute malnutrition
A27: Agnaramiteraka | B27: MG51507070057001 | C27: Treatment of moderate acute malnutrition
A28: Agnena | B28: MG51507190008001 | C28: Treatment of moderate acute malnutrition
A29: AGNENA CENTRE | B29: 605170018 | C29: School feeding (on-site)
A30: AGNENA SUD | B30: 605170017 | C30: School feeding (on-site)
A31: Agnena-Ankiliabo | B31: MG51507070076001 | C31: Treatment of moderate acute malnutrition
A32: Agnirinihamba | B32: MG52513030003001 | C32: Treatment of moderate acute malnutrition
A33: Agnivovorano | B33: MG52516151080009 | C33: Prevention of stunting
A34: Agnorike | B34: MG52516111017001 | C34: Treatment of moderate acute malnutrition
A35: AJAFARO | B35: MG52516170069001 | C35: Treatment of moderate acute malnutrition
A36: Akarana | B36: MG52518092089 | C36: Prevention of acute malnutrition
A37: AKILETOKA | B37: 609020028 | C37: School feeding (on-site)
A38: Akonatsy | B38: MG52518152051001 | C38: Treatment of moderate acute malnutrition
A39: AKONDRIA | B39: MG52518251077001 | C39: Treatment of moderate acute malnutrition
A40: Akororoky Mahazosoa | B40: MG52516071030 | C40: Prevention of acute malnutrition
A41: Alohavala | B41: MG25217051006001 | C41: Treatment of moderate acute malnutrition
A42: Ambahevahe | B42: MG51520358003001 | C42: Treatment of moderate acute malnutrition
...

Sheet Sheet3
A3: Adm4Code | B3: Adm4Name
A4: MG23209031001 | B4: Tsaravary
A5: MG23209050001 | B5: Mahatsara Sud
A6: MG23209070001 | B6: Tsiatosika
A7: MG23209110001 | B7: Marokarima
A8: MG23209110002 | B8: Ambaladara
A9: MG23209110056 | B9: Marohandriana
A10: MG23210070001 | B10: Ambila
A11: MG23210070003 | B11: Andriana
A12: MG23210070004 | B12: Loharano
A13: MG23210070005 | B13: Mandrosovelo
A14: MG23210070009 | B14: Beanana
... A1555: MG43404070006 | B1555: Ankadibe
A1556: Grand Total

Sheet Sheet5
A3: Adm4Name | B3: Adm4Code | C3: Adm2Name
A4: Agnivovorano | B4: MG52516151080 | C4: Antanimora Atsimo
A5: Ambalabe Beavoha | B5: MG51507310027 | C5: Ampanihy Ouest
A6: Ambaladara | B6: MG23209110002 | C6: Mananjary
A7: Ambalasaraka | B7: MG52518251003 | C7: Bekily
A8: Ambalatany | B8: MG51507290070 | C8: Ampanihy Ouest
A9: Ambalatany | B9: MG25213471001 | C9: Farafangana
A10: Ambalatsimiviky | B10: MG51507310039 | C10: Ampanihy Ouest
A11: Ambaro | B11: MG52516130039 | C11: Antanimora Atsimo
A12: Ambaro | B12: MG23209032002 | C12: Tsihombe
A13: Ambatofotsy | B13: MG24216192004 | C13: Bekily
A14: Ambatomena | B14: MG53519050024 | C14: Amboasary-Atsimo
... A1582: (blank) | B1582: (blank) | C1582: Sakaraha

Sheet Sheet7
A3: Adm1Name | B3: Adm1Code | F3: Adm2Name | G3: Adm2Code | J3: Adm3Name | K3: Adm3Code | L3: Adm2Name | M3: Adm1Name | P3: Adm4Name | Q3: Adm4Code | R3: Adm3Name | S3: Adm2Name | T3: Adm1Name
A4: Amoron I Mania | B4: MG22 | F4: AMBOASARY ATSIMO | G4: MG53519 | J4: Alakamisy | K4: MG12118050 | L4: ANTSIRABE II | M4: Vakinankaratra | P4: Adabolava Sud | Q4: MG53519190007 | R4: MAHALY | S4: Amboasary-Atsimo | T4: Anosy
A5: Androy | B5: MG52 | F5: Amboasary-Atsimo | G5: MG53519 | J5: Ambahikily | K5: MG51504050 | L5: Morombe | M5: Atsimo Andrefana | P5: AGNAFONDRAVOAY | Q5: MG53517150085 | R5: Analamary | S5: Ambovombe-Androy | T5: Androy
A6: Anosy | B6: MG53 | F6: Ambositra | G6: MG22203 | J6: AMBAHITA | K6: MG52518151 | L6: Bekily | M6: Androy | P6: AGNANILAHY | Q6: (blank) | R6: JAFARO | S6: Antanimora Atsimo | T6: Androy
A7: Atsimo Andrefana | B7: MG51 | F7: Ambovombe-Androy | G7: MG52516 | J7: Ambalasoa | K7: MG53517070 | L7: Betroka | M7: Anosy | P7: Agnaramiteraka | Q7: MG51507070057 | R7: Ankilimivory | S7: Ampanihy Ouest | T7: Atsimo Andrefana
A8: Atsimo Atsinanana | B8: MG25 | F8: Ampanihy Ouest | G8: MG51507 | J8: Ambalatany | K8: MG25213471 | L8: Farafangana | M8: Atsimo Atsinanana | P8: Agnena | Q8: MG51507070076 | R8: Ankiliabo | S8: Ampanihy Ouest | T8: Atsimo Andrefana
A9: Fitovinany | B9: MG23A | F9: Antanimora Atsimo | G9: MG52516a | J9: Ambalavato Antevato | K9: MG25213552 | L9: Farafangana | M9: Atsimo Atsinanana | Q9: MG52513010017 | R9: Mahaenegne | S9: BELOHA | T9: Androy
A10: ITASY | B10: MG13 | F10: Antanimora Sud | G10: MG52516a | J10: Ambalavato Nord | K10: MG25213410 | L10: Farafangana | M10: Atsimo Atsinanana | P10: Agnena Centre | Q10: MG51507190008 | R10: Ankilimivory | S10: Ampanihy Ouest | T10: Atsimo Andrefana
A11: Vakinankaratra | B11: MG12 | F11: ANTSIRABE II | G11: MG12118 | J11: AMBANISARIKA | K11: MG52516031 | L11: Ambovombe-Androy | M11: Androy | P11: Agnirinihamba | Q11: MG52513030003 | R11: Tranovaho | S11: BELOHA | T11: Androy
B12: MG42 | F12: Arivonimamo | G12: MG13105 | J12: Ambatoabo | K12: MG53515112 | L12: Taolagnaro | M12: Anosy | P12: Agnivovorano | Q12: MG52516151080 | R12: Andalatanosy | S12: Antanimora Atsimo | T12: Androy
A13: Vatovavy | B13: MG23 | F13: Befotaka | G13: MG25222 | J13: Ambatofotsy | K13: MG23211031 | L13: Ikongo | M13: Vatovavy | P13: Agnorike | Q13: MG52516111017 | R13: Sihanamaro | S13: Ambovombe-Androy | T13: Androy
F14: Bekily | G14: MG52518 | J14: Ambatolava | K14: MG25214212 | L14: Vangaindrano | M14: Atsimo Atsinanana | P14: AJAFARO | Q14: MG52516170069 | R14: JAFARO | S14: Ambovombe-Androy | T14: Androy
F15: BELOHA | G15: MG52513 | J15: AMBATOMAINTY | K15: MG33312031 | L15: Bekily | M15: Androy | P15: AKARANA | Q15: (blank) | R15: TANAMBAO TSIRANDRANY | S15: Bekily | T15: Androy
F16: Betioky Atsimo | G16: MG51506 | J16: Ambatomanjaka | K16: MG13112050 | L16: Miarinarivo | M16: ITASY | P16: Akonatsy | Q16: MG52518152051 | R16: MAROVIRO | S16: Bekily | T16: Androy
F17: Betroka | G17: MG53517 | J17: AMBATOMIVARY | K17: MG53517350 | L17: Betroka | M17: Anosy | P17: AKONDRIA | Q17: MG52518251077 | R17: Andalatanosy | S17: Ambovombe-Androy | T17: Androy
F18: Farafangana | G18: MG25213 | J18: AMBATOSOLA | K18: MG52518091 | L18: Bekily | M18: Androy | P18: AKOROROKY MAHAZOSOA | Q18: (blank) | R18: MAROALOMAINTY | S18: Ambovombe-Androy | T18: Androy
F19: Ifanadiana | G19: MG23206 | J19: AMBATOTSIVALA | K19: MG52513091a | L19: BELOHA | M19: Androy | P19: Alohavala | Q19: MG25217051006 | R19: Mahazoarivo | S19: Vondrozo | T19: Atsimo Atsinanana
F20: Ikongo | G20: MG23211 | J20: Ambatry Mitsinjo | K20: MG51506013 | L20: Betioky Atsimo | M20: Atsimo Andrefana | P20: Ambahita centrale | Q20: MG52518151045 | R20: AMBAHITA | S20: Bekily | T20: Androy
F21: Manakara Atsimo | G21: MG23210 | J21: AMBAZOA | K21: MG52516092 | L21: Ambovombe-Androy | M21: Androy | P21: AMBAHITA CENTRE | Q21: (blank) | R21: AMBAHITA | S21: Bekily | T21: Androy
F22: Manandriana | G22: MG22223 | J22: Ambila | K22: MG23210070 | L22: Manakara Atsimo | M22: Vatovavy | P22: Ambahivahy | Q22: MG51507050003 | R22: Amborompotsy | S22: Ampanihy Ouest | T22: Atsimo Andrefana
F23: Mananjary | G23: MG23209 | J23: Ambinany | K23: MG51512150 | L23: Sakaraha | M23: Atsimo Andrefana | Q23: MG51520358003 | R23: Beheloka | S23: Toliary-II | T23: Atsimo Andrefana
F24: Miarinarivo | G24: MG13112 | J24: Amboanjo | K24: MG23210171 | L24: Manakara Atsimo | M24: Vatovavy | P24: Ambahotera | Q24: MG51507090011 | R24: Maniry | S24: Ampanihy Ouest | T24: Atsimo Andrefana
F25: Midongy-Atsimo | G25: MG25215 | J25: Amboasary Atsimo | K25: MG53519010 | L25: Amboasary-Atsimo | M25: Anosy | P25: Ambahy Ianakafy | Q25: MG53519070006 | R25: Sampona | S25: Amboasary-Atsimo | T25: Anosy
F26: Morombe | G26: MG51504 | J26: Ambodinonoka | K26: MG23209391 | L26: Mananjary | M26: Vatovavy | P26: Ambalabe Beavoha | Q26: MG51507310027 | R26: Itampolo | S26: Ampanihy Ouest | T26: Atsimo Andrefana
F27: Sakaraha | G27: MG51512 | J27: Ambodirano | K27: MG25217030b | L27: Vondrozo | M27: Atsimo Atsinanana | P27: Ambalabe Mahatsara | Q27: MG25217030004 | R27: Ambodirano | S27: Vondrozo | T27: Atsimo Atsinanana
F28: Taolagnaro | G28: MG53515 | J28: Ambohibary | K28: MG12118331 | L28: ANTSIRABE II | M28: Vakinankaratra | P28: Ambaladara | Q28: MG23209110002 | R28: Marokarima | S28: Mananjary | T28: Vatovavy
F29: Toliary-I | G29: MG51501 | J29: Ambohigogo | K29: MG25213270 | L29: Farafangana | M29: Atsimo Atsinanana | P29: Ambaladoda | Q29: MG51507310043 | R29: Androipano | S29: Ampanihy Ouest | T29: Atsimo Andrefana
F30: Toliary-II | G30: MG51520 | J30: Ambohimahavelona | K30: MG51520111 | L30: Toliary-II | M30: Atsimo Andrefana | P30: Ambalagoavy | Q30: MG23211011007 | R30: Ikongo | S30: Ikongo | T30: Vatovavy
F31: Tsihombe | G31: MG52514 | J31: AMBOHIMALAZA | K31: MG52516033 | L31: Ambovombe-Androy | M31: Androy | P31: Ambalahazo | Q31: MG33312152009 | R31: Betioky Atsimo | S31: Betioky Atsimo | T31: Atsimo Andrefana
F32: Vangaindrano | G32: MG25214 | J32: Ambohimana | K32: MG25217090 | L32: Vondrozo | M32: Atsimo Atsinanana | P32: Ambalakazaha | Q32: MG41405090003 | R32: Andakana | S32: Vondrozo | T32: Atsimo Atsinanana
F33: Vohipeno | G33: MG23212 | J33: Ambohimandroso | K33: MG25213330 | L33: Farafangana | M33: Atsimo Atsinanana | P33: Ambalamasy | Q33: MG52513070061 | R33: Marolinta | S33: BELOHA | T33: Androy
F34: Vondrozo | G34: MG25217 | J34: Ambohimisafy | K34: MG23211092 | L34: Ikongo | M34: Vatovavy | P34: Ambalandambo | Q34: MG51507310090 | R34: Androipano | S34: Ampanihy Ouest | T34: Atsimo Andrefana
J35: Ambolomadinika | K35: MG23211012 | L35: Ikongo | M35: Vatovavy | P35: Ambalasaraka | Q35: MG52518251003 | R35: Beraketa | S35: Bekily | T35: Androy
J36: AMBONAIVO | K36: MG52516050 | L36: Ambovombe-Androy | M36: Androy | P36: Ambalatany | Q36: MG25213471001 | R36: Ambalatany | S36: Farafangana | T36: Atsimo Atsinanana
J37: AMBONDRO | K37: MG52516091 | L37: Ambovombe-Androy | M37: Androy | Q37: MG51507290070 | R37: Fotadrevo | S37: Ampanihy Ouest | T37: Atsimo Andrefana
J38: Ambongo | K38: MG25214211 | L38: Vangaindrano | M38: Atsimo Atsinanana | P38: Ambalatenina | Q38: MG31310130010 | R38: Ambatofotsy | S38: Ikongo | T38: Vatovavy
J39: Amborompotsy | K39: MG51507050 | L39: Ampanihy Ouest | M39: Atsimo Andrefana | P39: Ambalatraka | Q39: MG25213410001 | R39: Ambalavato Nord | S39: Farafangana | T39: Atsimo Atsinanana
J40: Amborondra | K40: MG23210430 | L40: Manakara Atsimo | M40: Vatovavy | P40: Ambalatsiefa | Q40: MG51506050020 | R40: Ampanihy Ouest | S40: Ampanihy Ouest | T40: Atsimo Andrefana
J41: Ambositra I | K41: MG22203010 | L41: Ambositra | M41: Amoron I Mania | P41: AMBALATSIMIVIKE | Q41: (blank) | R41: Androipano | S41: Ampanihy Ouest | T41: Atsimo Andrefana
J42: Ambositra II | K42: MG22203030 | L42: Ambositra | M42: Amoron I Mania | P42: Ambalatsimiviky | Q42: MG51507310039 | R42: Androipano | S42: Ampanihy Ouest | T42: Atsimo Andrefana
...

Sheet Sites
A2: ID | B2: Field_office | C2: Field_office_code | D2: Field_office_code_ancien | E2: Adm1Name | F2: Adm1Code | G2: Adm1Code_ancien | H2: Adm2Name | I2: Adm2Code | J2: Adm2Code_ancien | K2: Adm3Name | L2: Adm3Code | M2: Adm3Code_ancien | N2: Adm4Name | O2: Adm4Code | P2: Adm4Code_ancien | Q2: POIName | R2: POI_code | S2: POI_code_ancien | T2: Activity_tag | U2: Tag_Code | V2: HHCoord | W2: Longitude | X2: Latitude | Y2: Latest Visit | Z2: Performance
A3: =+R3&U3 -> 0SMP | B3: Antananarivo | C3: =+VLOOKUP(Sites_per_tag[[#This Row],[Field_office]],Parameter!$A$3:$B$11,2,0) -> 3 | E3: Vakinankaratra | F3: MG42 | H3: =PROPER(Sites_per_tag[[#This Row],[Adm2Name]]) -> Antsirabe Ii | I3: MG12118 | K3: Tsarahonenana | L3: MG12118350 | Q3: SOAMAHATAZANA | R3: 0 | T3: School feeding (on-site) | U3: =+VLOOKUP(Sites_per_tag[[#This Row],[Activity_tag]],Parameter!$A$24:$B$32,2,0) -> SMP | W3: 47.2636 | X3: -19.98722
A4: =+R4&U4 -> 111010003SMP | B4: Antananarivo | C4: =+VLOOKUP(Sites_per_tag[[#This Row],[Field_office]],Parameter!$A$3:$B$11,2,0) -> 3 | E4: Vakinankaratra | F4: MG12 | H4: =PROPER(Sites_per_tag[[#This Row],[Adm2Name]]) -> Antsirabe Ii | I4: MG12118 | K4: Alakamisy | L4: MG12118050 | Q4: MAHABODO | R4: 111010003 | T4: School feeding (on-site) | U4: =+VLOOKUP(Sites_per_tag[[#This Row],[Activity_tag]],Parameter!$A$24:$B$32,2,0) -> SMP | W4: 47.16427 | X4: -20.110253
A5: =+R5&U5 -> 111050003SMP | B5: Antananarivo | C5: =+VLOOKUP(Sites_per_tag[[#This Row],[Field_office]],Parameter!$A$3:$B$11,2,0) -> 3 | E5: Vakinankaratra | F5: MG12 | H5: =PROPER(Sites_per_tag[[#This Row],[Adm2Name]]) -> Antsirabe Ii | I5: MG12118 | K5: Ambohibary | L5: MG12118331 | Q5: AMBATOMAINTY-AMPETSAPETSA | R5: 111050003 | T5: School feeding (on-site) | U5: =+VLOOKUP(Sites_per_tag[[#This Row],[Activity_tag]],Parameter!$A$24:$B$32,2,0) -> SMP | W5: 47.0878 | X5: -19.51342
A6: =+R6&U6 -> 111050005SMP | B6: Antananarivo | C6: =+VLOOKUP(Sites_per_tag[[#This Row],[Field_office]],Parameter!$A$3:$B$11,2,0) -> 3 | E6: Vakinankaratra | F6: MG12 | H6: =PROPER(Sites_per_tag[[#This Row],[Adm2Name]]) -> Antsirabe Ii | I6: MG12118 | K6: Ambohibary | L6: MG12118331 | Q6: AMBOHIBARY | R6: 111050005 | T6: School feeding (on-site) | U6: =+VLOOKUP(Sites_per_tag[[#This Row],[Activity_tag]],Parameter!$A$24:$B$32,2,0) -> SMP | W6: 47.140737 | X6: -19.616846
A7: =+R7&U7 -> 111050007SMP | B7: Antananarivo | C7: =+VLOOKUP(Sites_per_tag[[#This Row],[Field_office]],Parameter!$A$3:$B$11,2,0) -> 3 | E7: Vakinankaratra | F7: MG12 | H7: =PROPER(Sites_per_tag[[#This Row],[Adm2Name]]) -> Antsirabe Ii | I7: MG12118 | K7: Ambohibary | L7: MG12118331 | Q7: AMBOHIMARINA | R7: 111050007 | T7: School feeding (on-site) | U7: =+VLOOKUP(Sites_per_tag[[#This Row],[Activity_tag]],Parameter!$A$24:$B$32,2,0) -> SMP | W7: 47.0878 | X7: -19.51342
A8: =+R8&U8 -> 111050009SMP | B8: Antananarivo | C8: =+VLOOKUP(Sites_per_tag[[#This Row],[Field_office]],Parameter!$A$3:$B$11,2,0) -> 3 | E8: Vakinankaratra | F8: MG12 | H8: =PROPER(Sites_per_tag[[#This Row],[Adm2Name]]) -> Antsirabe Ii | I8: MG12118 | K8: Ambohibary | L8: MG12118331 | Q8: AMBONIATSIMO | R8: 111050009 | T8: School feeding (on-site) | U8: =+VLOOKUP(Sites_per_tag[[#This Row],[Activity_tag]],Parameter!$A$24:$B$32,2,0) -> SMP | W8: 47.0878 | X8: -19.51342
A9: =+R9&U9 -> 111050012SMP | B9: Antananarivo | C9: =+VLOOKUP(Sites_per_tag[[#This Row],[Field_office]],Parameter!$A$3:$B$11,2,0) -> 3 | E9: Vakinankaratra | F9: MG12 | H9: =PROPER(Sites_per_tag[[#This Row],[Adm2Name]]) -> Antsirabe Ii | I9: MG12118 | K9: Ambohibary | L9: MG12118331 | Q9: ANOSY | R9: 111050012 | T9: School feeding (on-site) | U9: =+VLOOKUP(Sites_per_tag[[#This Row],[Activity_tag]],Parameter!$A$24:$B$32,2,0) -> SMP | W9: 47.0878 | X9: -19.51342
A10: =+R10&U10 -> 111050015SMP | B10: Antananarivo | C10: =+VLOOKUP(Sites_per_tag[[#This Row],[Field_office]],Parameter!$A$3:$B$11,2,0) -> 3 | E10: Vakinankaratra | F10: MG12 | H10: =PROPER(Sites_per_tag[[#This Row],[Adm2Name]]) -> Antsirabe Ii | I10: MG12118 | K10: Ambohibary | L10: MG12118331 | Q10: ANTSAPANDRANO | R10: 111050015 | T10: School feeding (on-site) | U10: =+VLOOKUP(Sites_per_tag[[#This Row],[Activity_tag]],Parameter!$A$24:$B$32,2,0) -> SMP | W10: 47.0878 | X10: -19.51342
A11: =+R11&U11 -> 111050016SMP | B11: Antananarivo | C11: =+VLOOKUP(Sites_per_tag[[#This Row],[Field_office]],Parameter!$A$3:$B$11,2,0) -> 3 | E11: Vakinankaratra | F11: MG12 | H11: =PROPER(Sites_per_tag[[#This Row],[Adm2Name]]) -> Antsirabe Ii | I11: MG12118 | K11: Ambohibary | L11: MG12118331 | Q11: FARAVOHITRA | R11: 111050016 | T11: School feeding (on-site) | U11: =+VLOOKUP(Sites_per_tag[[#This Row],[Activity_tag]],Parameter!$A$24:$B$32,2,0) -> SMP | W11: 47.0878 | X11: -19.51342
A12: =+R12&U12 -> 111050018SMP | B12: Antananarivo | C12: =+VLOOKUP(Sites_per_tag[[#This Row],[Field_office]],Parameter!$A$3:$B$11,2,0) -> 3 | E12: Vakinankaratra | F12: MG12 | H12: =PROPER(Sites_per_tag[[#This Row],[Adm2Name]]) -> Antsirabe Ii | I12: MG12118 | K12: Ambohibary | L12: MG12118331 | Q12: MANDRITSARA | R12: 111050018 | T12: School feeding (on-site) | U12: =+VLOOKUP(Sites_per_tag[[#This Row],[Activity_tag]],Parameter!$A$24:$B$32,2,0) -> SMP | W12: 47.0878 | X12: -19.51342
A13: =+R13&U13 -> 111050022SMP | B13: Antananarivo | C13: =+VLOOKUP(Sites_per_tag[[#This Row],[Field_office]],Parameter!$A$3:$B$11,2,0) -> 3 | E13: Vakinankaratra | F13: MG12 | H13: =PROPER(Sites_per_tag[[#This Row],[Adm2Name]]) -> Antsirabe Ii | I13: MG12118 | K13: Ambohibary | L13: MG12118331 | Q13: SAMBAINA GARA | R13: 111050022 | T13: School feeding (on-site) | U13: =+VLOOKUP(Sites_per_tag[[#This Row],[Activity_tag]],Parameter!$A$24:$B$32,2,0) -> SMP | W13: 47.0878 | X13: -19.51342
A14: =+R14&U14 -> 111100002SMP | B14: Antananarivo | C14: =+VLOOKUP(Sites_per_tag[[#This Row],[Field_office]],Parameter!$A$3:$B$11,2,0) -> 3 | E14: Vakinankaratra | F14: MG12 | H14: =PROPER(Sites_per_tag[[#This Row],[Adm2Name]]) -> Antsirabe Ii | I14: MG12118 | K14: Antanambao | L14: MG12118370 | Q14: ANTOMBINANDRIANA | R14: 111100002 | T14: School feeding (on-site) | U14: =+VLOOKUP(Sites_per_tag[[#This Row],[Activity_tag]],Parameter!$A$24:$B$32,2,0) -> SMP | W14: 47.37375 | X14: -20.00165
... A1280: =+R1280&U1280 -> 621080040SMP | B1280: Ambovombe | C1280: =+VLOOKUP(Sites_per_tag[[#This Row],[Field_office]],Parameter!$A$3:$B$11,2,0) -> 6 | E1280: Androy | F1280: MG52 | H1280: =PROPER(Sites_per_tag[[#This Row],[Adm2Name]]) -> Tsihombe | I1280: MG52514 | K1280: Nikoly | L1280: MG52514012 | Q1280: NAMOIA | R1280: 621080040 | T1280: School feeding (on-site) | U1280: =+VLOOKUP(Sites_per_tag[[#This Row],[Activity_tag]],Parameter!$A$24:$B$32,2,0) -> SMP | W1280: 45.445308 | X1280: -25.401261
A1281: =+R1281&U1281 -> MG23209031001001STUNT | B1281: Manakara | C1281: =+VLOOKUP(Sites_per_tag[[#This Row],[Field_office]],Parameter!$A$3:$B$11,2,0) -> 4 | E1281: Vatovavy | F1281: MG23 | H1281: =PROPER(Sites_per_tag[[#This Row],[Adm2Name]]) -> Mananjary | I1281: MG23209 | K1281: Tsaravary | L1281: MG23209031 | N1281: Tsaravary | O1281: MG23209031001 | Q1281: Tsaravary | R1281: MG23209031001001 | T1281: Prevention of stunting | U1281: =+VLOOKUP(Sites_per_tag[[#This Row],[Activity_tag]],Parameter!$A$24:$B$32,2,0) -> STUNT | V1281: 48.29978 -21.23748 | W1281: 48.29978 | X1281: -21.23748
A1282: =+R1282&U1282 -> MG23209032002001MAM | B1282: Ambovombe | C1282: =+VLOOKUP(Sites_per_tag[[#This Row],[Field_office]],Parameter!$A$3:$B$11,2,0) -> 6 | E1282: Androy | F1282: MG52 | H1282: =PROPER(Sites_per_tag[[#This Row],[Adm2Name]]) -> Tsihombe | I1282: MG52514 | K1282: Marovato | L1282: MG52514050 | N1282: Ambaro | O1282: MG23209032002 | Q1282: Ambaro | R1282: MG23209032002001 | T1282: Treatment of moderate acute malnutrition | U1282: =+VLOOKUP(Sites_per_tag[[#This Row],[Activity_tag]],Parameter!$A$24:$B$32,2,0) -> MAM | W1282: 45.275901 | X1282: -25.500785
A1283: =+R1283&U1283 -> MG23209050001001STUNT | B1283: Manakara | C1283: =+VLOOKUP(Sites_per_tag[[#This Row],[Field_office]],Parameter!$A$3:$B$11,2,0) -> 4 | E1283: Vatovavy | F1283: MG23 | H1283: =PROPER(Sites_per_tag[[#This Row],[Adm2Name]]) -> Mananjary | I1283: MG23209 | K1283: Mahatsara Sud | L1283: MG23209050 | N1283: Mahatsara Sud | O1283: MG23209050001 | Q1283: Mahatsara Sud | R1283: MG23209050001001 | T1283: Prevention of stunting | U1283: =+VLOOKUP(Sites_per_tag[[#This Row],[Activity_tag]],Parameter!$A$24:$B$32,2,0) -> STUNT | V1283: 48.3196 -21.16913 | W1283: 48.3196 | X1283: -21.16913
A1284: =+R1284&U1284 -> MG23209050001PREV | B1284: Manakara | C1284: =+VLOOKUP(Sites_per_tag[[#This Row],[Field_office]],Parameter!$A$3:$B$11,2,0) -> 4 | E1284: Vatovavy | F1284: MG23 | H1284: =PROPER(Sites_per_tag[[#This Row],[Adm2Name]]) -> Mananjary | I1284: MG23209 | K1284: Mahatsara Sud | L1284: MG23209050 | N1284: Mahatsara Sud(Lavakianja) | Q1284: Mahatsara Sud(Lavakianja) | R1284: MG23209050001 | T1284: Prevention of acute malnutrition | U1284: =+VLOOKUP(Sites_per_tag[[#This Row],[Activity_tag]],Parameter!$A$24:$B$32,2,0) -> PREV | W1284: 48.29487 | X1284: -21.17837
A1285: =+R1285&U1285 -> MG23209070001001STUNT | B1285: Manakara | C1285: =+VLOOKUP(Sites_per_tag[[#This Row],[Field_office]],Parameter!$A$3:$B$11,2,0) -> 4 | E1285: Vatovavy | F1285: MG23 | H1285: =PROPER(Sites_per_tag[[#This Row],[Adm2Name]]) -> Mananjary | I1285: MG23209 | K1285: Tsiatosika | L1285: MG23209070 | N1285: Tsiatosika | O1285: MG23209070001 | Q1285: Tsiatosika | R1285: MG23209070001001 | T1285: Prevention of stunting | U1285: =+VLOOKUP(Sites_per_tag[[#This Row],[Activity_tag]],Parameter!$A$24:$B$32,2,0) -> STUNT | V1285: 48.23018 -21.1757 | W1285: 48.23018 | X1285: -21.1757
A1286: =+R1286&U1286 -> MG23209070001PREV | B1286: Manakara | C1286: =+VLOOKUP(Sites_per_tag[[#This Row],[Field_office]],Parameter!$A$3:$B$11,2,0) -> 4 | E1286: Vatovavy | F1286: MG23 | H1286: =PROPER(Sites_per_tag[[#This Row],[Adm2Name]]) -> Mananjary | I1286: MG23209 | K1286: Tsiatosika | L1286: MG23209070 | N1286: Tsiatosika | Q1286: Tsiatosika | R1286: MG23209070001 | T1286: Prevention of acute malnutrition | U1286: =+VLOOKUP(Sites_per_tag[[#This Row],[Activity_tag]],Parameter!$A$24:$B$32,2,0) -> PREV | W1286: 48.22485 | X1286: -21.2026
A1287: =+R1287&U1287 -> MG23209070055PREV | B1287: Manakara | C1287: =+VLOOKUP(Sites_per_tag[[#This Row],[Field_office]],Parameter!$A$3:$B$11,2,0) -> 4 | E1287: Vatovavy | F1287: MG23 | H1287: =PROPER(Sites_per_tag[[#This Row],[Adm2Name]]) -> Mananjary | I1287: MG23209 | K1287: Tsiatosika | L1287: MG23209070 | N1287: Anivorano | Q1287: Anivorano | R1287: MG23209070055 | T1287: Prevention of acute malnutrition | U1287: =+VLOOKUP(Sites_per_tag[[#This Row],[Activity_tag]],Parameter!$A$24:$B$32,2,0) -> PREV | W1287: 48.25255 | X1287: -21.10902
A1288: =+R1288&U1288 -> MG23209070066PREV | B1288: Manakara | C1288: =+VLOOKUP(Sites_per_tag[[#This Row],[Field_office]],Parameter!$A$3:$B$11,2,0) -> 4 | E1288: Vatovavy | F1288: MG23 | H1288: =PROPER(Sites_per_tag[[#This Row],[Adm2Name]]) -> Mananjary | I1288: MG23209 | K1288: Tsiatosika | L1288: MG23209070 | N1288: Ambohimiarina I | Q1288: Ambohimiarina I | R1288: MG23209070066 | T1288: Prevention of acute malnutrition | U1288: =+VLOOKUP(Sites_per_tag[[#This Row],[Activity_tag]],Parameter!$A$24:$B$32,2,0) -> PREV | W1288: 48.18883 | X1288: -21.19037
A1289: =+R1289&U1289 -> MG23209070077PREV | B1289: Manakara | C1289: =+VLOOKUP(Sites_per_tag[[#This Row],[Field_office]],Parameter!$A$3:$B$11,2,0) -> 4 | E1289: Vatovavy | F1289: MG23 | H1289: =PROPER(Sites_per_tag[[#This Row],[Adm2Name]]) -> Mananjary | I1289: MG23209 | K1289: Tsiatosika | L1289: MG23209070 | N1289: Ankarongana | Q1289: Ankarongana | R1289: MG23209070077 | T1289: Prevention of acute malnutrition | U1289: =+VLOOKUP(Sites_per_tag[[#This Row],[Activity_tag]],Parameter!$A$24:$B$32,2,0) -> PREV | W1289: 48.25255 | X1289: -21.10902
A1290: =+R1290&U1290 -> MG23209110001001STUNT | B1290: Manakara | C1290: =+VLOOKUP(Sites_per_tag[[#This Row],[Field_office]],Parameter!$A$3:$B$11,2,0) -> 4 | E1290: Vatovavy | F1290: MG23 | H1290: =PROPER(Sites_per_tag[[#This Row],[Adm2Name]]) -> Mananjary | I1290: MG23209 | K1290: Marokarima | L1290: MG23209110 | N1290: Marokarima | O1290: MG23209110001 | Q1290: Marokarima | R1290: MG23209110001001 | T1290: Prevention of stunting | U1290: =+VLOOKUP(Sites_per_tag[[#This Row],[Activity_tag]],Parameter!$A$24:$B$32,2,0) -> STUNT | V1290: 48.13763 -21.23452 | W1290: 48.13763 | X1290: -21.23452
A1291: =+R1291&U1291 -> MG23209110002001STUNT | B1291: Manakara | C1291: =+VLOOKUP(Sites_per_tag[[#This Row],[Field_office]],Parameter!$A$3:$B$11,2,0) -> 4 | E1291: Vatovavy | F1291: MG23 | H1291: =PROPER(Sites_per_tag[[#This Row],[Adm2Name]]) -> Mananjary | I1291: MG23209 | K1291: Marokarima | L1291: MG23209110 | N1291: Ambaladara | O1291: MG23209110002 | Q1291: Ambaladara | R1291: MG23209110002001 | T1291: Prevention of stunting | U1291: =+VLOOKUP(Sites_per_tag[[#This Row],[Activity_tag]],Parameter!$A$24:$B$32,2,0) -> STUNT | V1291: 48.10883 -21.16095 | W1291: 48.10883 | X1291: -21.16095
A1292: =+R1292&U1292 -> MG23209110056001STUNT | B1292: Manakara | C1292: =+VLOOKUP(Sites_per_tag[[#This Row],[Field_office]],Parameter!$A$3:$B$11,2,0) -> 4 | E1292: Vatovavy | F1292: MG23 | H1292: =PROPER(Sites_per_tag[[#This Row],[Adm2Name]]) -> Mananjary | I1292: MG23209 | K1292: Marokarima | L1292: MG23209110 | N1292: Marohandriana | O1292: MG23209110056 | Q1292: Marohandriana | R1292: MG23209110056001 | T1292: Prevention of stunting | U1292: =+VLOOKUP(Sites_per_tag[[#This Row],[Activity_tag]],Parameter!$A$24:$B$32,2,0) -> STUNT | V1292: 48.12778 -21.29582 | W1292: 48.12778 | X1292: -21.29582
A1293: =+R1293&U1293 -> MG23209170001PREV | B1293: Manakara | C1293: =+VLOOKUP(Sites_per_tag[[#This Row],[Field_office]],Parameter!$A$3:$B$11,2,0) -> 4 | E1293: Vatovavy | F1293: MG23 | H1293: =PROPER(Sites_per_tag[[#This Row],[Adm2Name]]) -> Mananjary | I1293: MG23209 | K1293: Marosangy | L1293: MG23209170 | N1293: Marosangy | Q1293: Marosangy | R1293: MG23209170001 | T1293: Prevention of acute malnutrition | U1293: =+VLOOKUP(Sites_per_tag[[#This Row],[Activity_tag]],Parameter!$A$24:$B$32,2,0) -> PREV | W1293: 48.28652 | X1293: -21.00638
A1294: =+R1294&U1294 -> MG23209170056PREV | B1294: Manakara | C1294: =+VLOOKUP(Sites_per_tag[[#This Row],[Field_office]],Parameter!$A$3:$B$11,2,0) -> 4 | E1294: Vatovavy | F1294: MG23 | H1294: =PROPER(Sites_per_tag[[#This Row],[Adm2Name]]) -> Mananjary | I1294: MG23209 | K1294: Marosangy | L1294: MG23209170 | N1294: Ambohimahasoa | Q1294: Ambohimahasoa | R1294: MG23209170056 | T1294: Prevention of acute malnutrition | U1294: =+VLOOKUP(Sites_per_tag[[#This Row],[Activity_tag]],Parameter!$A$24:$B$32,2,0) -> PREV | W1294: 48.25322 | X1294: -20.95078
A1295: =+R1295&U1295 -> MG23209230007001MAM | B1295: Manakara | C1295: =+VLOOKUP(Sites_per_tag[[#This Row],[Field_office]],Parameter!$A$3:$B$11,2,0) -> 4 | E1295: Vatovavy | F1295: MG23 | H1295: =PROPER(Sites_per_tag[[#This Row],[Adm2Name]]) -> Ikongo | I1295: MG23211 | K1295: Ambohimisafy | L1295: MG23211092 | N1295: Lavakianja | O1295: MG23209230007 | Q1295: LAVAKIANJA | R1295: MG23209230007001 | T1295: Treatment of moderate acute malnutrition | U1295: =+VLOOKUP(Sites_per_tag[[#This Row],[Activity_tag]],Parameter!$A$24:$B$32,2,0) -> MAM | W1295: 47.556879 | X1295: -21.491142
A1296: =+R1296&U1296 -> MG23209270001PREV | B1296: Manakara | C1296: =+VLOOKUP(Sites_per_tag[[#This Row],[Field_office]],Parameter!$A$3:$B$11,2,0) -> 4 | E1296: Vatovavy | F1296: MG23 | H1296: =PROPER(Sites_per_tag[[#This Row],[Adm2Name]]) -> Mananjary | I1296: MG23209 | K1296: Mahavoky Nord | L1296: MG23209270 | N1296: Mahavoky Nord | Q1296: Mahavoky Nord | R1296: MG23209270001 | T1296: Prevention of acute malnutrition | U1296: =+VLOOKUP(Sites_per_tag[[#This Row],[Activity_tag]],Parameter!$A$24:$B$32,2,0) -> PREV | W1296: 48.3018 | X1296: -20.84758
A1297: =+R1297&U1297 -> MG23209290011001MAM | B1297: Manakara | C1297: =+VLOOKUP(Sites_per_tag[[#This Row],[Field_office]],Parameter!$A$3:$B$11,2,0) -> 4 | E1297: Vatovavy | F1297: MG23 | H1297: =PROPER(Sites_per_tag[[#This Row],[Adm2Name]]) -> Ikongo | I1297: MG23211 | K1297: Ambatofotsy | L1297: MG23211031 | N1297: Mahasoa | O1297: MG23209290011 | Q1297: MAHASOA | R1297: MG23209290011001 | T1297: Treatment of moderate acute malnutrition | U1297: =+VLOOKUP(Sites_per_tag[[#This Row],[Activity_tag]],Parameter!$A$24:$B$32,2,0) -> MAM | W1297: 47.495319 | X1297: -21.79685
A1298: =+R1298&U1298 -> MG23210070001001STUNT | B1298: Manakara | C1298: =+VLOOKUP(Sites_per_tag[[#This Row],[Field_office]],Parameter!$A$3:$B$11,2,0) -> 4 | E1298: Vatovavy | F1298: MG23 | H1298: =PROPER(Sites_per_tag[[#This Row],[Adm2Name]]) -> Manakara Atsimo | I1298: MG23210 | K1298: Ambila | L1298: MG23210070 | N1298: Ambila | O1298: MG23210070001 | Q1298: Ambila | R1298: MG23210070001001 | T1298: Prevention of stunting | U1298: =+VLOOKUP(Sites_per_tag[[#This Row],[Activity_tag]],Parameter!$A$24:$B$32,2,0) -> STUNT | V1298: 47.9706 -22.00342 | W1298: 47.9706 | X1298: -22.00342
A1299: =+R1299&U1299 -> MG23210070003001STUNT | B1299: Manakara | C1299: =+VLOOKUP(Sites_per_tag[[#This Row],[Field_office]],Parameter!$A$3:$B$11,2,0) -> 4 | E1299: Vatovavy | F1299: MG23 | H1299: =PROPER(Sites_per_tag[[#This Row],[Adm2Name]]) -> Manakara Atsimo | I1299: MG23210 | K1299: Ambila | L1299: MG23210070 | N1299: Andriana | O1299: MG23210070003 | Q1299: Andriana | R1299: MG23210070003001 | T1299: Prevention of stunting | U1299: =+VLOOKUP(Sites_per_tag[[#This Row],[Activity_tag]],Parameter!$A$24:$B$32,2,0) -> STUNT | V1299: 47.96397 -21.93935 | W1299: 47.96397 | X1299: -21.93935
A1300: =+R1300&U1300 -> MG23210070004001STUNT | B1300: Manakara | C1300: =+VLOOKUP(Sites_per_tag[[#This Row],[Field_office]],Parameter!$A$3:$B$11,2,0) -> 4 | E1300: Vatovavy | F1300: MG23 | H1300: =PROPER(Sites_per_tag[[#This Row],[Adm2Name]]) -> Manakara Atsimo | I1300: MG23210 | K1300: Ambila | L1300: MG23210070 | N1300: Loharano | O1300: MG23210070004 | Q1300: Loharano | R1300: MG23210070004001 | T1300: Prevention of stunting | U1300: =+VLOOKUP(Sites_per_tag[[#This Row],[Activity_tag]],Parameter!$A$24:$B$32,2,0) -> STUNT | V1300: 48.10508 -21.95043 | W1300: 48.10508 | X1300: -21.95043
A1301: =+R1301&U1301 -> MG23210070005001STUNT | B1301: Manakara | C1301: =+VLOOKUP(Sites_per_tag[[#This Row],[Field_office]],Parameter!$A$3:$B$11,2,0) -> 4 | E1301: Vatovavy | F1301: MG23 | H1301: =PROPER(Sites_per_tag[[#This Row],[Adm2Name]]) -> Manakara Atsimo | I1301: MG23210 | K1301: Ambila | L1301: MG23210070 | N1301: Mandrosovelo | O1301: MG23210070005 | Q1301: Mandrosovelo | R1301: MG23210070005001 | T1301: Prevention of stunting | U1301: =+VLOOKUP(Sites_per_tag[[#This Row],[Activity_tag]],Parameter!$A$24:$B$32,2,0) -> STUNT | V1301: 47.99585 -21.9573 | W1301: 47.99585 | X1301: -21.9573
A1302: =+R1302&U1302 -> MG23210070009001STUNT | B1302: Manakara | C1302: =+VLOOKUP(Sites_per_tag[[#This Row],[Field_office]],Parameter!$A$3:$B$11,2,0) -> 4 | E1302: Vatovavy | F1302: MG23 | H1302: =PROPER(Sites_per_tag[[#This Row],[Adm2Name]]) -> Manakara Atsimo | I1302: MG23210 | K1302: Ambila | L1302: MG23210070 | N1302: Beanana | O1302: MG23210070009 | Q1302: Beanana | R1302: MG23210070009001 | T1302: Prevention of stunting | U1302: =+VLOOKUP(Sites_per_tag[[#This Row],[Activity_tag]],Parameter!$A$24:$B$32,2,0) -> STUNT | V1302: 48.00023 -22.0064 | W1302: 48.00023 | X1302: -22.0064
A1303: =+R1303&U1303 -> MG23210070055001STUNT | B1303: Manakara | C1303: =+VLOOKUP(Sites_per_tag[[#This Row],[Field_office]],Parameter!$A$3:$B$11,2,0) -> 4 | E1303: Vatovavy | F1303: MG23 | H1303: =PROPER(Sites_per_tag[[#This Row],[Adm2Name]]) -> Manakara Atsimo | I1303: MG23210 | K1303: Ambila | L1303: MG23210070 | N1303: Beretra | O1303: MG23210070055 | Q1303: Beretra | R1303: MG23210070055001 | T1303: Prevention of stunting | U1303: =+VLOOKUP(Sites_per_tag[[#This Row],[Activity_tag]],Parameter!$A$24:$B$32,2,0) -> STUNT | V1303: 47.9272 -21.97237 | W1303: 47.9272 | X1303: -21.97237
A1304: =+R1304&U1304 -> MG23210190003001MAM | B1304: Manakara | C1304: =+VLOOKUP(Sites_per_tag[[#This Row],[Field_office]],Parameter!$A$3:$B$11,2,0) -> 4 | E1304: Atsimo Atsinanana | F1304: MG25 | H1304: =PROPER(Sites_per_tag[[#This Row],[Adm2Name]]) -> Farafangana | I1304: MG25213 | K1304: Mahavelo | L1304: MG25213150 | N1304: Anivotsara | O1304: MG23210190003 | Q1304: Anivotsara | R1304: MG23210190003001 | T1304: Treatment of moderate acute malnutrition | U1304: =+VLOOKUP(Sites_per_tag[[#This Row],[Activity_tag]],Parameter!$A$24:$B$32,2,0) -> MAM | W1304: 47.71413 | X1304: -22.71685
A1305: =+R1305&U1305 -> MG23210190005001MAM | B1305: Manakara | C1305: =+VLOOKUP(Sites_per_tag[[#This Row],[Field_office]],Parameter!$A$3:$B$11,2,0) -> 4 | E1305: Vatovavy | F1305: MG23 | H1305: =PROPER(Sites_per_tag[[#This Row],[Adm2Name]]) -> Ikongo | I1305: MG23211 | K1305: Ikongo | L1305: MG23211011 | N1305: Ambohimiary | O1305: MG23210190005 | Q1305: AMBOHIMIARY | R1305: MG23210190005001 | T1305: Treatment of moderate acute malnutrition | U1305: =+VLOOKUP(Sites_per_tag[[#This Row],[Activity_tag]],Parameter!$A$24:$B$32,2,0) -> MAM | W1305: 47.3541 | X1305: -21.85525
A1306: =+R1306&U1306 -> MG23210271003001MAM | B1306: Manakara | C1306: =+VLOOKUP(Sites_per_tag[[#This Row],[Field_office]],Parameter!$A$3:$B$11,2,0) -> 4 | E1306: Atsimo Atsinanana | F1306: MG25 | H1306: =PROPER(Sites_per_tag[[#This Row],[Adm2Name]]) -> Vangaindrano | I1306: MG25214 | K1306: Tsiately | L1306: MG25214050 | N1306: Tsararano | O1306: MG23210271003 | Q1306: Tsararano(Com Tsiately) | R1306: MG23210271003001 | T1306: Treatment of moderate acute malnutrition | U1306: =+VLOOKUP(Sites_per_tag[[#This Row],[Activity_tag]],Parameter!$A$24:$B$32,2,0) -> MAM | W1306: 47.68962 | X1306: -23.28825
...

Sheet Parameter
A3: Field_office | B3: Field_office_code | C3: Field_office_code_ancien
A4: Bekily | B4: 1
A5: Fort Dauphin | B5: 2
A6: Antananarivo | B6: 3
A7: Manakara | B7: 4
A8: Ambovombe | B8: 6
A9: Tulear | B9: 10
A10: Ampanihy | B10: 9
A11: Tsihombe | B11: 7
A14: EnuPartner | B14: EnuPartner_Code | C14: EnuPartner_Code_ancien
A15: Association TOMPY | B15: 1
A16: LALANA | B16: 2
A17: MAHAVOTSE | B17: 3
A18: ONG AINA | B18: 4
A19: YP | B19: 6
A20: WFP | B20: 7
A21: Others | B21: 999
A24: Activity tag | B24: tag*
A25: Food assistance for asset | B25: FFA
A26: Forecast-based Anticipatory Actions | B26: FBA
A27: General Distribution | B27: GD
A28: Prevention of acute malnutrition | B28: PREV
A29: Prevention of stunting | B29: STUNT
A30: School feeding (on-site) | B30: SMP
A31: Smallholder agricultural market support Activities | B31: SMS
A32: Treatment of moderate acute malnutrition | B32: MAM
